<mujoco model="1-tet-1">
  <compiler angle="radian" meshdir="assets" autolimits="true"/>
  <option gravity="0 0 -9.81" timestep="0.002" integrator="implicit"/>

  <option cone="elliptic" impratio="10"/>

  <asset>
    <material name="metal" rgba="0.58 0.58 0.58 1"/>
    <material name="gray" rgba="0.4627 0.4627 0.4627 1"/>
    <material name="red" rgba="0.9 0.1 0.1 1"/>
    <texture name="grid" type="2d" builtin="checker" width="512" height="512" rgb1=".1 .2 .3" rgb2=".2 .3 .4"/>
    <material name="grid" texture="grid" texrepeat="1 1" texuniform="true" reflectance=".2"/>
  </asset>

  <worldbody>
  <body name="ground" pos="0 0 0">
  <freejoint/>

    <body name="[0-1-0]" pos="0.000000 0.000000 0.000000" >

    <geom type="cylinder" pos="0.029142 0.499150 0.000000" axisangle="-0.998300 0.058284 0.000000 1.570796" size="0.025 0.45" material="metal" contype="1"/>
    <body name="[0-1-1]" pos="0.029142 0.499150 0.000000" >
        <geom type="cylinder" pos="0.013724 0.235060 0.000000" axisangle="-0.998300 0.058284 0.000000 1.570796" size="0.02 0.5" material="gray" contype="1"/>
        <joint name="Linear-0-1" type="slide" axis="0.058284 0.998300 0.000000" range="-0.235460 0.714540"/>

    <body name="[1-2-0]" pos="0.042865 0.734210 0.000000" >
    <joint name="Passive1-2" type="ball" pos="0.000000 0.000000 0.000000" axis="0 1 0" damping=".9"/>
    <geom type="cylinder" pos="0.417706 -0.274813 0.000000" axisangle="0.549625 0.835411 -0.000000 1.570796" size="0.025 0.45" material="metal" contype="1"/>
    <body name="[1-2-1]" pos="0.417706 -0.274813 0.000000" >
        <geom type="cylinder" pos="0.196706 -0.129415 0.000000" axisangle="0.549625 0.835411 -0.000000 1.570796" size="0.02 0.5" material="gray" contype="1"/>
        <joint name="Linear-1-2" type="slide" axis="0.835411 -0.549625 0.000000" range="-0.235460 0.714540"/>

    <body name="[2-3-0]" pos="0.614412 -0.404228 0.000000" >
    <joint name="Passive2-3" type="ball" pos="0.000000 0.000000 0.000000" axis="0 1 0" damping=".9"/>
    <geom type="cylinder" pos="-0.288184 0.016825 0.408248" axisangle="-0.033650 -0.576369 0.000000 0.615480" size="0.025 0.45" material="metal" contype="1"/>
    <body name="[2-3-1]" pos="-0.288184 0.016825 0.408248" >
        <geom type="cylinder" pos="-0.135712 0.007923 0.192252" axisangle="-0.033650 -0.576369 0.000000 0.615480" size="0.02 0.5" material="gray" contype="1"/>
        <joint name="Linear-2-3" type="slide" axis="-0.576369 0.033650 0.816497" range="-0.235460 0.714540"/>

    </body>
    </body>

    <body name="[2-4-0]" pos="0.614412 -0.404228 0.000000" >
    <joint name="Passive2-4" type="ball" pos="0.000000 0.000000 0.000000" axis="0 1 0" damping=".9"/>
    <geom type="cylinder" pos="-0.207912 0.138836 0.433009" axisangle="-0.277673 -0.415824 0.000000 0.523612" size="0.025 0.45" material="metal" contype="1"/>
    <body name="[2-4-1]" pos="-0.207912 0.138836 0.433009" >
        <geom type="cylinder" pos="-0.097910 0.065381 0.203913" axisangle="-0.277673 -0.415824 0.000000 0.523612" size="0.02 0.5" material="gray" contype="1"/>
        <joint name="Linear-2-4" type="slide" axis="-0.415824 0.277673 0.866019" range="-0.235460 0.714540"/>

    </body>
    </body>

    </body>
    </body>

    <body name="[1-3-0]" pos="0.042865 0.734210 0.000000" >
    <joint name="Passive1-3" type="ball" pos="0.000000 0.000000 0.000000" axis="0 1 0" damping=".9"/>
    <geom type="cylinder" pos="0.129521 -0.257988 0.408248" axisangle="0.515975 0.259042 -0.000000 0.615480" size="0.025 0.45" material="metal" contype="1"/>
    <body name="[1-3-1]" pos="0.129521 -0.257988 0.408248" >
        <geom type="cylinder" pos="0.060994 -0.121492 0.192252" axisangle="0.515975 0.259042 -0.000000 0.615480" size="0.02 0.5" material="gray" contype="1"/>
        <joint name="Linear-1-3" type="slide" axis="0.259042 -0.515975 0.816497" range="-0.235460 0.714540"/>

    </body>
    </body>

    <body name="[1-4-0]" pos="0.042865 0.734210 0.000000" >
    <joint name="Passive1-4" type="ball" pos="0.000000 0.000000 0.000000" axis="0 1 0" damping=".9"/>
    <geom type="cylinder" pos="0.209794 -0.135976 0.433009" axisangle="0.271953 0.419587 -0.000000 0.523612" size="0.025 0.45" material="metal" contype="1"/>
    <body name="[1-4-1]" pos="0.209794 -0.135976 0.433009" >
        <geom type="cylinder" pos="0.098796 -0.064034 0.203913" axisangle="0.271953 0.419587 -0.000000 0.523612" size="0.02 0.5" material="gray" contype="1"/>
        <joint name="Linear-1-4" type="slide" axis="0.419587 -0.271953 0.866019" range="-0.235460 0.714540"/>

    </body>
    </body>

    </body>
    </body>

    <body name="[0-2-0]" pos="0.000000 0.000000 0.000000" >
    <joint name="Passive0-2" type="ball" pos="0.000000 0.000000 0.000000" axis="0 1 0" damping=".9"/>
    <geom type="cylinder" pos="0.446848 0.224337 0.000000" axisangle="-0.448675 0.893695 0.000000 1.570796" size="0.025 0.45" material="metal" contype="1"/>
    <body name="[0-2-1]" pos="0.446848 0.224337 0.000000" >
        <geom type="cylinder" pos="0.210430 0.105645 0.000000" axisangle="-0.448675 0.893695 0.000000 1.570796" size="0.02 0.5" material="gray" contype="1"/>
        <joint name="Linear-0-2" type="slide" axis="0.893695 0.448675 0.000000" range="-0.235460 0.714540"/>

    </body>
    </body>

    <body name="[0-3-0]" pos="0.000000 0.000000 0.000000" >
    <joint name="Passive0-3" type="ball" pos="0.000000 0.000000 0.000000" axis="0 1 0" damping=".9"/>
    <geom type="cylinder" pos="0.158663 0.241162 0.408248" axisangle="-0.482325 0.317326 0.000000 0.615480" size="0.025 0.45" material="metal" contype="1"/>
    <body name="[0-3-1]" pos="0.158663 0.241162 0.408248" >
        <geom type="cylinder" pos="0.074718 0.113568 0.192252" axisangle="-0.482325 0.317326 0.000000 0.615480" size="0.02 0.5" material="gray" contype="1"/>
        <joint name="Linear-0-3" type="slide" axis="0.317326 0.482325 0.816497" range="-0.235460 0.714540"/>

    </body>
    </body>
    </body> </worldbody> <equality>
<connect name="kinematic_link_0-0" active="true" body1="[0-2-1]" body2="[1-2-1]" anchor=" 0.657277 0.329982 0.000000" />
<connect name="kinematic_link_1-0" active="true" body1="[0-3-1]" body2="[1-3-1]" anchor=" 0.233381 0.354731 0.600501" />
<connect name="kinematic_link_1-1" active="true" body1="[0-3-1]" body2="[2-3-1]" anchor=" 0.233381 0.354731 0.600501" />
<connect name="kinematic_link_2-0" active="true" body1="[1-3-1]" body2="[0-3-1]" anchor=" 0.190515 -0.379479 0.600501" />
<connect name="kinematic_link_2-1" active="true" body1="[1-3-1]" body2="[2-3-1]" anchor=" 0.190515 -0.379479 0.600501" />
<connect name="kinematic_link_3-0" active="true" body1="[1-4-1]" body2="[2-4-1]" anchor=" 0.308590 -0.200010 0.636922" />
<connect name="kinematic_link_4-0" active="true" body1="[2-3-1]" body2="[0-3-1]" anchor=" -0.423896 0.024748 0.600501" />
<connect name="kinematic_link_4-1" active="true" body1="[2-3-1]" body2="[1-3-1]" anchor=" -0.423896 0.024748 0.600501" />
<connect name="kinematic_link_5-0" active="true" body1="[2-4-1]" body2="[1-4-1]" anchor=" -0.305822 0.204217 0.636922" /></equality><actuator>

<intvelocity name="Member-1-2" joint="Linear-1-2" kp="18000"  kv="10000" inheritrange="1" />
<intvelocity name="Member-1-3" joint="Linear-1-3" kp="18000"  kv="10000" inheritrange="1" />
<intvelocity name="Member-1-4" joint="Linear-1-4" kp="18000"  kv="10000" inheritrange="1" />
<intvelocity name="Member-0-1" joint="Linear-0-1" kp="18000"  kv="10000" inheritrange="1" />
<intvelocity name="Member-0-2" joint="Linear-0-2" kp="18000"  kv="10000" inheritrange="1" />
<intvelocity name="Member-0-3" joint="Linear-0-3" kp="18000"  kv="10000" inheritrange="1" />
<intvelocity name="Member-2-3" joint="Linear-2-3" kp="18000"  kv="10000" inheritrange="1" />
<intvelocity name="Member-2-4" joint="Linear-2-4" kp="18000"  kv="10000" inheritrange="1" /></actuator>
</mujoco>