<mujoco model="1-tet">
  <compiler angle="radian" meshdir="assets" autolimits="true"/>
  <option gravity="0 0 -9.81" timestep="0.002" integrator="implicit"/>

  <option cone="elliptic" impratio="10"/>

  <asset>
    <material name="metal" rgba="0.58 0.58 0.58 1"/>
    <material name="gray" rgba="0.4627 0.4627 0.4627 1"/>
    <material name="red" rgba="0.9 0.1 0.1 1"/>
    <texture name="grid" type="2d" builtin="checker" width="512" height="512" rgb1=".1 .2 .3" rgb2=".2 .3 .4"/>
    <material name="grid" texture="grid" texrepeat="1 1" texuniform="true" reflectance=".2"/>
  </asset>

  <worldbody>
  <body name="ground" pos="0 0 0">
  <freejoint/>

    <body name="[0-1-0]" pos="0.000000 0.000000 0.000000" >
    <geom type="sphere" name="(0)" pos="0 0 0" size="0.1" material="red"contype="1" mass="10"/>
    <geom type="cylinder" pos="0.490554 -0.096728 -0.000000" axisangle="0.193456 0.981109 -0.000000 1.570796" size="0.025 0.45" material="metal" contype="1"/>
    <body name="[0-1-1]" pos="0.490554 -0.096728 -0.000000" >
        <geom type="cylinder" pos="0.223586 -0.044087 -0.000000" axisangle="0.193456 0.981109 -0.000000 1.570796" size="0.02 0.5" material="gray" contype="1"/>
        <joint name="Linear-0-1" type="slide" axis="0.981109 -0.193456 -0.000000" range="-0.227892 0.722108"/>

    <body name="[1-2-0]" pos="0.714141 -0.140815 -0.000000" >
    <geom type="sphere" name="(1)" pos="0 0 0" size="0.1" material="red"contype="1" mass="10"/>
    <joint name="Passive1-2" type="ball" pos="0.000000 0.000000 0.000000" axis="0 1 0" damping=".9"/>
    <geom type="cylinder" pos="-0.161508 0.473197 -0.000000" axisangle="-0.946393 -0.323017 0.000000 1.570796" size="0.025 0.45" material="metal" contype="1"/>
    <body name="[1-2-1]" pos="-0.161508 0.473197 -0.000000" >
        <geom type="cylinder" pos="-0.073613 0.215675 -0.000000" axisangle="-0.946393 -0.323017 0.000000 1.570796" size="0.02 0.5" material="gray" contype="1"/>
        <joint name="Linear-1-2" type="slide" axis="-0.323017 0.946393 -0.000000" range="-0.227892 0.722108"/>

    <body name="[2-3-0]" pos="-0.235121 0.688872 -0.000000" >
    <geom type="sphere" name="(2)" pos="0 0 0" size="0.1" material="red"contype="1" mass="10"/>
    <joint name="Passive2-3" type="ball" pos="0.000000 0.000000 0.000000" axis="0 1 0" damping=".9"/>
    <geom type="cylinder" pos="-0.055846 -0.283222 0.408248" axisangle="0.566444 -0.111692 0.000000 0.615480" size="0.025 0.45" material="metal" contype="1"/>
    <body name="[2-3-1]" pos="-0.055846 -0.283222 0.408248" >
        <geom type="cylinder" pos="-0.025454 -0.129088 0.186073" axisangle="0.566444 -0.111692 0.000000 0.615480" size="0.02 0.5" material="gray" contype="1"/>
        <joint name="Linear-2-3" type="slide" axis="-0.111692 -0.566444 0.816497" range="-0.227892 0.722108"/>

    </body>
    </body>

    </body>
    </body>

    <body name="[1-3-0]" pos="0.714141 -0.140815 -0.000000" >
    <joint name="Passive1-3" type="ball" pos="0.000000 0.000000 0.000000" axis="0 1 0" damping=".9"/>
    <geom type="cylinder" pos="-0.217354 0.189975 0.408248" axisangle="-0.379950 -0.434709 0.000000 0.615480" size="0.025 0.45" material="metal" contype="1"/>
    <body name="[1-3-1]" pos="-0.217354 0.189975 0.408248" >
        <geom type="cylinder" pos="-0.099066 0.086587 0.186073" axisangle="-0.379950 -0.434709 0.000000 0.615480" size="0.02 0.5" material="gray" contype="1"/>
        <joint name="Linear-1-3" type="slide" axis="-0.434709 0.379950 0.816497" range="-0.227892 0.722108"/>

    </body>
    </body>

    </body>
    </body>

    <body name="[0-2-0]" pos="0.000000 0.000000 0.000000" >
    <joint name="Passive0-2" type="ball" pos="0.000000 0.000000 0.000000" axis="0 1 0" damping=".9"/>
    <geom type="cylinder" pos="0.329046 0.376469 -0.000000" axisangle="-0.752937 0.658092 0.000000 1.570796" size="0.025 0.45" material="metal" contype="1"/>
    <body name="[0-2-1]" pos="0.329046 0.376469 -0.000000" >
        <geom type="cylinder" pos="0.149974 0.171588 -0.000000" axisangle="-0.752937 0.658092 0.000000 1.570796" size="0.02 0.5" material="gray" contype="1"/>
        <joint name="Linear-0-2" type="slide" axis="0.658092 0.752937 -0.000000" range="-0.227892 0.722108"/>

    </body>
    </body>

    <body name="[0-3-0]" pos="0.000000 0.000000 0.000000" >
    <joint name="Passive0-3" type="ball" pos="0.000000 0.000000 0.000000" axis="0 1 0" damping=".9"/>
    <geom type="cylinder" pos="0.273200 0.093247 0.408248" axisangle="-0.186494 0.546400 0.000000 0.615480" size="0.025 0.45" material="metal" contype="1"/>
    <body name="[0-3-1]" pos="0.273200 0.093247 0.408248" >
        <geom type="cylinder" pos="0.124520 0.042500 0.186073" axisangle="-0.186494 0.546400 0.000000 0.615480" size="0.02 0.5" material="gray" contype="1"/>
        <joint name="Linear-0-3" type="slide" axis="0.546400 0.186494 0.816497" range="-0.227892 0.722108"/>
        <geom type="sphere" name="(3)" pos="0 0 0" size="0.1" material="red"contype="1" mass="10"/>


    </body>
    </body>
    </body> </worldbody> <equality>
<connect name="kinematic_link_0-0" active="true" body1="[0-2-1]" body2="[1-2-1]" anchor=" 0.479020 0.548057 -0.000000" />
<connect name="kinematic_link_1-0" active="true" body1="[0-3-1]" body2="[1-3-1]" anchor=" 0.397720 0.135747 0.594321" />
<connect name="kinematic_link_1-1" active="true" body1="[0-3-1]" body2="[2-3-1]" anchor=" 0.397720 0.135747 0.594321" />
<connect name="kinematic_link_2-0" active="true" body1="[1-3-1]" body2="[0-3-1]" anchor=" -0.316421 0.276562 0.594321" />
<connect name="kinematic_link_2-1" active="true" body1="[1-3-1]" body2="[2-3-1]" anchor=" -0.316421 0.276562 0.594321" />
<connect name="kinematic_link_3-0" active="true" body1="[2-3-1]" body2="[0-3-1]" anchor=" -0.081300 -0.412309 0.594321" />
<connect name="kinematic_link_3-1" active="true" body1="[2-3-1]" body2="[1-3-1]" anchor=" -0.081300 -0.412309 0.594321" /></equality><actuator>


<intvelocity name="Member-0-1" joint="Linear-0-1" kp="18000"  kv="10000" inheritrange="1" />
<intvelocity name="Member-0-2" joint="Linear-0-2" kp="18000"  kv="10000" inheritrange="1" />
<intvelocity name="Member-0-3" joint="Linear-0-3" kp="18000"  kv="10000" inheritrange="1" />
<intvelocity name="Member-0-4" joint="Linear-0-1" kp="1"  kv="1" inheritrange="1" />
<intvelocity name="Member-0-5" joint="Linear-0-1" kp="1"  kv="1" inheritrange="1" />
<intvelocity name="Member-1-2" joint="Linear-1-2" kp="18000"  kv="10000" inheritrange="1" />
<intvelocity name="Member-1-3" joint="Linear-1-3" kp="18000"  kv="10000" inheritrange="1" />
<intvelocity name="Member-1-4" joint="Linear-0-1" kp="1"  kv="1" inheritrange="1" />
<intvelocity name="Member-1-5" joint="Linear-0-1" kp="1"  kv="1" inheritrange="1" />
<intvelocity name="Member-2-3" joint="Linear-2-3" kp="18000"  kv="10000" inheritrange="1" />
<intvelocity name="Member-2-4" joint="Linear-0-1" kp="1"  kv="1" inheritrange="1" />
<intvelocity name="Member-2-5" joint="Linear-0-1" kp="1"  kv="1" inheritrange="1" />
<intvelocity name="Member-3-4" joint="Linear-0-1" kp="1"  kv="1" inheritrange="1" />
<intvelocity name="Member-3-5" joint="Linear-0-1" kp="1"  kv="1" inheritrange="1" />
<intvelocity name="Member-4-5" joint="Linear-0-1" kp="1"  kv="1" inheritrange="1" />
</actuator>
</mujoco>