<mujoco model="2-tet">
  <compiler angle="radian" meshdir="assets" autolimits="true"/>
  <option gravity="0 0 -9.81" timestep="0.002" integrator="implicit"/>

  <option cone="elliptic" impratio="10"/>

  <asset>
    <material name="metal" rgba="0.58 0.58 0.58 1"/>
    <material name="gray" rgba="0.4627 0.4627 0.4627 1"/>
    <material name="red" rgba="0.9 0.1 0.1 1"/>
    <texture name="grid" type="2d" builtin="checker" width="512" height="512" rgb1=".1 .2 .3" rgb2=".2 .3 .4"/>
    <material name="grid" texture="grid" texrepeat="1 1" texuniform="true" reflectance=".2"/>
  </asset>

  <worldbody>
  <body name="ground" pos="0 0 0">
  <freejoint/>

    <body name="[0-1-0]" pos="0.000000 0.000000 0.000000" >

    <geom type="cylinder" pos="0.494917 0.071110 0.000000" axisangle="-0.142221 0.989835 0.000000 1.570796" size="0.025 0.45" material="metal" contype="1"/>
    <body name="[0-1-1]" pos="0.494917 0.071110 0.000000" >
        <geom type="cylinder" pos="0.236071 0.033919 0.000000" axisangle="-0.142221 0.989835 0.000000 1.570796" size="0.02 0.5" material="gray" contype="1"/>
        <joint name="Linear-0-1" type="slide" axis="0.989835 0.142221 0.000000" range="-0.238495 0.711505"/>

    <body name="[1-2-0]" pos="0.730988 0.105029 0.000000" >
    <joint name="Passive1-2" type="ball" pos="0.000000 0.000000 0.000000" axis="0 1 0" damping=".9"/>
    <geom type="cylinder" pos="-0.309042 0.393056 0.000000" axisangle="-0.786112 -0.618084 0.000000 1.570796" size="0.025 0.45" material="metal" contype="1"/>
    <body name="[1-2-1]" pos="-0.309042 0.393056 0.000000" >
        <geom type="cylinder" pos="-0.147410 0.187484 0.000000" axisangle="-0.786112 -0.618084 0.000000 1.570796" size="0.02 0.5" material="gray" contype="1"/>
        <joint name="Linear-1-2" type="slide" axis="-0.618084 0.786112 0.000000" range="-0.238495 0.711505"/>

    <body name="[2-3-0]" pos="-0.456452 0.580540 0.000000" >
    <joint name="Passive2-3" type="ball" pos="0.000000 0.000000 0.000000" axis="0 1 0" damping=".9"/>
    <geom type="cylinder" pos="0.041056 -0.285741 0.408248" axisangle="0.571481 0.082111 -0.000000 0.615480" size="0.025 0.45" material="metal" contype="1"/>
    <body name="[2-3-1]" pos="0.041056 -0.285741 0.408248" >
        <geom type="cylinder" pos="0.019583 -0.136296 0.194730" axisangle="0.571481 0.082111 -0.000000 0.615480" size="0.02 0.5" material="gray" contype="1"/>
        <joint name="Linear-2-3" type="slide" axis="0.082111 -0.571481 0.816497" range="-0.238495 0.711505"/>

    <body name="[3-4-0]" pos="0.060639 -0.422036 0.602979" >
    <joint name="Passive3-4" type="ball" pos="0.000000 0.000000 0.000000" axis="0 1 0" damping=".9"/>
    <geom type="cylinder" pos="0.378218 0.297376 -0.136083" axisangle="-0.594752 0.756436 0.000000 1.846439" size="0.025 0.45" material="metal" contype="1"/>
    <body name="[3-4-1]" pos="0.378218 0.297376 -0.136083" >
        <geom type="cylinder" pos="0.180406 0.141845 -0.064910" axisangle="-0.594752 0.756436 0.000000 1.846439" size="0.02 0.5" material="gray" contype="1"/>
        <joint name="Linear-3-4" type="slide" axis="0.756436 0.594752 -0.272166" range="-0.238495 0.711505"/>

    </body>
    </body>

    </body>
    </body>

    <body name="[2-4-0]" pos="-0.456452 0.580540 0.000000" >
    <joint name="Passive2-4" type="ball" pos="0.000000 0.000000 0.000000" axis="0 1 0" damping=".9"/>
    <geom type="cylinder" pos="0.419274 0.011635 0.272166" axisangle="-0.023270 0.838548 0.000000 0.995205" size="0.025 0.45" material="metal" contype="1"/>
    <body name="[2-4-1]" pos="0.419274 0.011635 0.272166" >
        <geom type="cylinder" pos="0.199989 0.005550 0.129820" axisangle="-0.023270 0.838548 0.000000 0.995205" size="0.02 0.5" material="gray" contype="1"/>
        <joint name="Linear-2-4" type="slide" axis="0.838548 0.023270 0.544331" range="-0.238495 0.711505"/>

    </body>
    </body>

    </body>
    </body>

    <body name="[1-3-0]" pos="0.730988 0.105029 0.000000" >
    <joint name="Passive1-3" type="ball" pos="0.000000 0.000000 0.000000" axis="0 1 0" damping=".9"/>
    <geom type="cylinder" pos="-0.267987 0.107315 0.408248" axisangle="-0.214630 -0.535973 0.000000 0.615480" size="0.025 0.45" material="metal" contype="1"/>
    <body name="[1-3-1]" pos="-0.267987 0.107315 0.408248" >
        <geom type="cylinder" pos="-0.127827 0.051188 0.194730" axisangle="-0.214630 -0.535973 0.000000 0.615480" size="0.02 0.5" material="gray" contype="1"/>
        <joint name="Linear-1-3" type="slide" axis="-0.535973 0.214630 0.816497" range="-0.238495 0.711505"/>

    </body>
    </body>

    <body name="[1-4-0]" pos="0.730988 0.105029 0.000000" >
    <joint name="Passive1-4" type="ball" pos="0.000000 0.000000 0.000000" axis="0 1 0" damping=".9"/>
    <geom type="cylinder" pos="0.110232 0.404691 0.272166" axisangle="-0.809382 0.220463 0.000000 0.995205" size="0.025 0.45" material="metal" contype="1"/>
    <body name="[1-4-1]" pos="0.110232 0.404691 0.272166" >
        <geom type="cylinder" pos="0.052579 0.193034 0.129820" axisangle="-0.809382 0.220463 0.000000 0.995205" size="0.02 0.5" material="gray" contype="1"/>
        <joint name="Linear-1-4" type="slide" axis="0.220463 0.809382 0.544331" range="-0.238495 0.711505"/>

    </body>
    </body>

    </body>
    </body>

    <body name="[0-2-0]" pos="0.000000 0.000000 0.000000" >
    <joint name="Passive0-2" type="ball" pos="0.000000 0.000000 0.000000" axis="0 1 0" damping=".9"/>
    <geom type="cylinder" pos="0.185875 0.464166 0.000000" axisangle="-0.928333 0.371751 0.000000 1.570796" size="0.025 0.45" material="metal" contype="1"/>
    <body name="[0-2-1]" pos="0.185875 0.464166 0.000000" >
        <geom type="cylinder" pos="0.088661 0.221403 0.000000" axisangle="-0.928333 0.371751 0.000000 1.570796" size="0.02 0.5" material="gray" contype="1"/>
        <joint name="Linear-0-2" type="slide" axis="0.371751 0.928333 0.000000" range="-0.238495 0.711505"/>

    </body>
    </body>

    <body name="[0-3-0]" pos="0.000000 0.000000 0.000000" >
    <joint name="Passive0-3" type="ball" pos="0.000000 0.000000 0.000000" axis="0 1 0" damping=".9"/>
    <geom type="cylinder" pos="0.226931 0.178426 0.408248" axisangle="-0.356851 0.453862 0.000000 0.615480" size="0.025 0.45" material="metal" contype="1"/>
    <body name="[0-3-1]" pos="0.226931 0.178426 0.408248" >
        <geom type="cylinder" pos="0.108244 0.085107 0.194730" axisangle="-0.356851 0.453862 0.000000 0.615480" size="0.02 0.5" material="gray" contype="1"/>
        <joint name="Linear-0-3" type="slide" axis="0.453862 0.356851 0.816497" range="-0.238495 0.711505"/>

    </body>
    </body>
    </body> </worldbody> <equality>
<connect name="kinematic_link_0-0" active="true" body1="[0-2-1]" body2="[1-2-1]" anchor=" 0.274536 0.685569 0.000000" />
<connect name="kinematic_link_1-0" active="true" body1="[0-3-1]" body2="[1-3-1]" anchor=" 0.335175 0.263533 0.602979" />
<connect name="kinematic_link_1-1" active="true" body1="[0-3-1]" body2="[2-3-1]" anchor=" 0.335175 0.263533 0.602979" />
<connect name="kinematic_link_2-0" active="true" body1="[1-3-1]" body2="[0-3-1]" anchor=" -0.395813 0.158503 0.602979" />
<connect name="kinematic_link_2-1" active="true" body1="[1-3-1]" body2="[2-3-1]" anchor=" -0.395813 0.158503 0.602979" />
<connect name="kinematic_link_3-0" active="true" body1="[1-4-1]" body2="[2-4-1]" anchor=" 0.162811 0.597725 0.401986" />
<connect name="kinematic_link_3-1" active="true" body1="[1-4-1]" body2="[3-4-1]" anchor=" 0.162811 0.597725 0.401986" />
<connect name="kinematic_link_4-0" active="true" body1="[2-4-1]" body2="[1-4-1]" anchor=" 0.619263 0.017185 0.401986" />
<connect name="kinematic_link_4-1" active="true" body1="[2-4-1]" body2="[3-4-1]" anchor=" 0.619263 0.017185 0.401986" />
<connect name="kinematic_link_5-0" active="true" body1="[3-4-1]" body2="[1-4-1]" anchor=" 0.558625 0.439221 -0.200993" />
<connect name="kinematic_link_5-1" active="true" body1="[3-4-1]" body2="[2-4-1]" anchor=" 0.558625 0.439221 -0.200993" /></equality><actuator>

<intvelocity name="Member-1-2" joint="Linear-1-2" kp="18000"  kv="10000" inheritrange="1" />
<intvelocity name="Member-1-3" joint="Linear-1-3" kp="18000"  kv="10000" inheritrange="1" />
<intvelocity name="Member-1-4" joint="Linear-1-4" kp="18000"  kv="10000" inheritrange="1" />
<intvelocity name="Member-0-1" joint="Linear-0-1" kp="18000"  kv="10000" inheritrange="1" />
<intvelocity name="Member-0-2" joint="Linear-0-2" kp="18000"  kv="10000" inheritrange="1" />
<intvelocity name="Member-0-3" joint="Linear-0-3" kp="18000"  kv="10000" inheritrange="1" />
<intvelocity name="Member-2-3" joint="Linear-2-3" kp="18000"  kv="10000" inheritrange="1" />
<intvelocity name="Member-2-4" joint="Linear-2-4" kp="18000"  kv="10000" inheritrange="1" />
<intvelocity name="Member-3-4" joint="Linear-3-4" kp="18000"  kv="10000" inheritrange="1" /></actuator>
</mujoco>