<mujoco model="2-tet">
  <compiler angle="radian" meshdir="assets" autolimits="true"/>
  <option gravity="0 0 -9.81" timestep="0.002" integrator="implicit"/>

  <option cone="elliptic" impratio="10"/>

  <asset>
    <material name="metal" rgba="0.58 0.58 0.58 1"/>
    <material name="gray" rgba="0.4627 0.4627 0.4627 1"/>
    <material name="red" rgba="0.9 0.1 0.1 1"/>
    <texture name="grid" type="2d" builtin="checker" width="512" height="512" rgb1=".1 .2 .3" rgb2=".2 .3 .4"/>
    <material name="grid" texture="grid" texrepeat="1 1" texuniform="true" reflectance=".2"/>
  </asset>

  <worldbody>
  <body name="ground" pos="0 0 0">
  <freejoint/>

    <body name="[0-1-0]" pos="0.000000 0.000000 0.000000" >
    <geom type="sphere" name="(0)" pos="0.000000 0.000000 0.000000" size="0.05" material="red"contype="1" mass="10"/>

    <geom type="cylinder" pos="0.450201 0.217530 -0.000000" axisangle="-0.435060 0.900401 0.000000 1.570796" size="0.025 0.45" material="metal" contype="1"/>
    <body name="[0-1-1]" pos="0.450201 0.217530 -0.000000" >
        <geom type="cylinder" pos="0.214741 0.103760 -0.000000" axisangle="-0.435060 0.900401 0.000000 1.570796" size="0.02 0.5" material="gray" contype="1"/>
        <joint name="Linear-0-1" type="slide" axis="0.900401 0.435060 -0.000000" range="-0.238495 0.711505"/>


    <body name="[1-2-0]" pos="0.664942 0.321290 -0.000000" >
    <geom type="sphere" name="(1)" pos="0.000000 0.000000 0.000000" size="0.05" material="red"contype="1" mass="10"/>
    <joint name="Passive1-2" type="ball" pos="0.000000 0.000000 0.000000" axis="0 1 0" damping=".9"/>
    <geom type="cylinder" pos="-0.413487 0.281120 0.000000" axisangle="-0.562240 -0.826974 0.000000 1.570796" size="0.025 0.45" material="metal" contype="1"/>
    <body name="[1-2-1]" pos="-0.413487 0.281120 0.000000" >
        <geom type="cylinder" pos="-0.197229 0.134092 0.000000" axisangle="-0.562240 -0.826974 0.000000 1.570796" size="0.02 0.5" material="gray" contype="1"/>
        <joint name="Linear-1-2" type="slide" axis="-0.826974 0.562240 0.000000" range="-0.238495 0.711505"/>


    <body name="[2-3-0]" pos="-0.610716 0.415212 0.000000" >
    <geom type="sphere" name="(2)" pos="0.000000 0.000000 0.000000" size="0.05" material="red"contype="1" mass="10"/>
    <joint name="Passive2-3" type="ball" pos="0.000000 0.000000 0.000000" axis="0 1 0" damping=".9"/>
    <geom type="cylinder" pos="0.125591 -0.259923 0.408248" axisangle="0.519847 0.251182 -0.000000 0.615480" size="0.025 0.45" material="metal" contype="1"/>
    <body name="[2-3-1]" pos="0.125591 -0.259923 0.408248" >
        <geom type="cylinder" pos="0.059906 -0.123981 0.194730" axisangle="0.519847 0.251182 -0.000000 0.615480" size="0.02 0.5" material="gray" contype="1"/>
        <joint name="Linear-2-3" type="slide" axis="0.251182 -0.519847 0.816497" range="-0.238495 0.711505"/>


    <body name="[3-4-0]" pos="0.185497 -0.383904 0.602979" >
    <geom type="sphere" name="(3)" pos="0.000000 0.000000 0.000000" size="0.05" material="red"contype="1" mass="10"/>
    <joint name="Passive3-4" type="ball" pos="0.000000 0.000000 0.000000" axis="0 1 0" damping=".9"/>
    <geom type="cylinder" pos="0.270508 0.397878 -0.136083" axisangle="-0.795756 0.541016 0.000000 1.846439" size="0.025 0.45" material="metal" contype="1"/>
    <body name="[3-4-1]" pos="0.270508 0.397878 -0.136083" >
        <geom type="cylinder" pos="0.129030 0.189784 -0.064910" axisangle="-0.795756 0.541016 0.000000 1.846439" size="0.02 0.5" material="gray" contype="1"/>
        <joint name="Linear-3-4" type="slide" axis="0.541016 0.795756 -0.272166" range="-0.238495 0.711505"/>
        <geom type="sphere" name="(4)" pos="0.399538 0.587662 -0.200993" size="0.05" material="red"contype="1" mass="10"/>

    </body>
    </body>

    </body>
    </body>

    <body name="[2-4-0]" pos="-0.610716 0.415212 0.000000" >

    <joint name="Passive2-4" type="ball" pos="0.000000 0.000000 0.000000" axis="0 1 0" damping=".9"/>
    <geom type="cylinder" pos="0.396099 0.137955 0.272166" axisangle="-0.275909 0.792198 0.000000 0.995205" size="0.025 0.45" material="metal" contype="1"/>
    <body name="[2-4-1]" pos="0.396099 0.137955 0.272166" >
        <geom type="cylinder" pos="0.188935 0.065803 0.129820" axisangle="-0.275909 0.792198 0.000000 0.995205" size="0.02 0.5" material="gray" contype="1"/>
        <joint name="Linear-2-4" type="slide" axis="0.792198 0.275909 0.544331" range="-0.238495 0.711505"/>


    </body>
    </body>

    </body>
    </body>

    <body name="[1-3-0]" pos="0.664942 0.321290 -0.000000" >

    <joint name="Passive1-3" type="ball" pos="0.000000 0.000000 0.000000" axis="0 1 0" damping=".9"/>
    <geom type="cylinder" pos="-0.287896 0.021197 0.408248" axisangle="-0.042393 -0.575792 0.000000 0.615480" size="0.025 0.45" material="metal" contype="1"/>
    <body name="[1-3-1]" pos="-0.287896 0.021197 0.408248" >
        <geom type="cylinder" pos="-0.137323 0.010111 0.194730" axisangle="-0.042393 -0.575792 0.000000 0.615480" size="0.02 0.5" material="gray" contype="1"/>
        <joint name="Linear-1-3" type="slide" axis="-0.575792 0.042393 0.816497" range="-0.238495 0.711505"/>


    </body>
    </body>

    <body name="[1-4-0]" pos="0.664942 0.321290 -0.000000" >

    <joint name="Passive1-4" type="ball" pos="0.000000 0.000000 0.000000" axis="0 1 0" damping=".9"/>
    <geom type="cylinder" pos="-0.017388 0.419075 0.272166" axisangle="-0.838149 -0.034776 0.000000 0.995205" size="0.025 0.45" material="metal" contype="1"/>
    <body name="[1-4-1]" pos="-0.017388 0.419075 0.272166" >
        <geom type="cylinder" pos="-0.008294 0.199894 0.129820" axisangle="-0.838149 -0.034776 0.000000 0.995205" size="0.02 0.5" material="gray" contype="1"/>
        <joint name="Linear-1-4" type="slide" axis="-0.034776 0.838149 0.544331" range="-0.238495 0.711505"/>


    </body>
    </body>

    </body>
    </body>

    <body name="[0-2-0]" pos="0.000000 0.000000 0.000000" >

    <joint name="Passive0-2" type="ball" pos="0.000000 0.000000 0.000000" axis="0 1 0" damping=".9"/>
    <geom type="cylinder" pos="0.036714 0.498650 0.000000" axisangle="-0.997301 0.073427 0.000000 1.570796" size="0.025 0.45" material="metal" contype="1"/>
    <body name="[0-2-1]" pos="0.036714 0.498650 0.000000" >
        <geom type="cylinder" pos="0.017512 0.237851 0.000000" axisangle="-0.997301 0.073427 0.000000 1.570796" size="0.02 0.5" material="gray" contype="1"/>
        <joint name="Linear-0-2" type="slide" axis="0.073427 0.997301 0.000000" range="-0.238495 0.711505"/>


    </body>
    </body>

    <body name="[0-3-0]" pos="0.000000 0.000000 0.000000" >

    <joint name="Passive0-3" type="ball" pos="0.000000 0.000000 0.000000" axis="0 1 0" damping=".9"/>
    <geom type="cylinder" pos="0.162305 0.238727 0.408248" axisangle="-0.477454 0.324610 0.000000 0.615480" size="0.025 0.45" material="metal" contype="1"/>
    <body name="[0-3-1]" pos="0.162305 0.238727 0.408248" >
        <geom type="cylinder" pos="0.077418 0.113870 0.194730" axisangle="-0.477454 0.324610 0.000000 0.615480" size="0.02 0.5" material="gray" contype="1"/>
        <joint name="Linear-0-3" type="slide" axis="0.324610 0.477454 0.816497" range="-0.238495 0.711505"/>


    </body>
    </body>
    </body> </worldbody> <equality>
<connect name="kinematic_link_0-0" active="true" body1="[0-2-1]" body2="[1-2-1]" anchor=" 0.054226 0.736502 0.000000" />
<connect name="kinematic_link_1-0" active="true" body1="[0-3-1]" body2="[1-3-1]" anchor=" 0.239723 0.352597 0.602979" />
<connect name="kinematic_link_1-1" active="true" body1="[0-3-1]" body2="[2-3-1]" anchor=" 0.239723 0.352597 0.602979" />
<connect name="kinematic_link_2-0" active="true" body1="[1-3-1]" body2="[0-3-1]" anchor=" -0.425219 0.031307 0.602979" />
<connect name="kinematic_link_2-1" active="true" body1="[1-3-1]" body2="[2-3-1]" anchor=" -0.425219 0.031307 0.602979" />
<connect name="kinematic_link_3-0" active="true" body1="[1-4-1]" body2="[2-4-1]" anchor=" -0.025682 0.618969 0.401986" />
<connect name="kinematic_link_3-1" active="true" body1="[1-4-1]" body2="[3-4-1]" anchor=" -0.025682 0.618969 0.401986" />
<connect name="kinematic_link_4-0" active="true" body1="[2-4-1]" body2="[1-4-1]" anchor=" 0.585034 0.203758 0.401986" />
<connect name="kinematic_link_4-1" active="true" body1="[2-4-1]" body2="[3-4-1]" anchor=" 0.585034 0.203758 0.401986" />
<connect name="kinematic_link_5-0" active="true" body1="[3-4-1]" body2="[1-4-1]" anchor=" 0.399538 0.587662 -0.200993" />
<connect name="kinematic_link_5-1" active="true" body1="[3-4-1]" body2="[2-4-1]" anchor=" 0.399538 0.587662 -0.200993" /></equality><actuator>

<intvelocity name="Member-0-1" joint="Linear-0-1" kp="18000"  kv="10000" inheritrange="1" />
<intvelocity name="Member-0-2" joint="Linear-0-2" kp="18000"  kv="10000" inheritrange="1" />
<intvelocity name="Member-0-3" joint="Linear-0-3" kp="18000"  kv="10000" inheritrange="1" />
<intvelocity name="Member-0-4" joint="Linear-0-1" kp="1"  kv="1" inheritrange="1" />
<intvelocity name="Member-0-5" joint="Linear-0-1" kp="1"  kv="1" inheritrange="1" />
<intvelocity name="Member-1-2" joint="Linear-1-2" kp="18000"  kv="10000" inheritrange="1" />
<intvelocity name="Member-1-3" joint="Linear-1-3" kp="18000"  kv="10000" inheritrange="1" />
<intvelocity name="Member-1-4" joint="Linear-1-4" kp="18000"  kv="10000" inheritrange="1" />
<intvelocity name="Member-1-5" joint="Linear-0-1" kp="1"  kv="1" inheritrange="1" />
<intvelocity name="Member-2-3" joint="Linear-2-3" kp="18000"  kv="10000" inheritrange="1" />
<intvelocity name="Member-2-4" joint="Linear-0-1" kp="1"  kv="1" inheritrange="1" />
<intvelocity name="Member-2-5" joint="Linear-0-1" kp="1"  kv="1" inheritrange="1" />
<intvelocity name="Member-3-4" joint="Linear-3-4" kp="18000"  kv="10000" inheritrange="1" />
<intvelocity name="Member-3-5" joint="Linear-0-1" kp="1"  kv="1" inheritrange="1" />
<intvelocity name="Member-4-5" joint="Linear-0-1" kp="1"  kv="1" inheritrange="1" />
</actuator>
</mujoco>
