<mujoco model="octahedron">
  <compiler angle="radian" meshdir="assets" autolimits="true"/>
  <option gravity="0 0 -9.81" timestep="0.002" integrator="implicit"/>

  <option cone="elliptic" impratio="10"/>

  <asset>
    <material name="metal" rgba="0.58 0.58 0.58 1"/>
    <material name="gray" rgba="0.4627 0.4627 0.4627 1"/>
    <material name="red" rgba="0.9 0.1 0.1 1"/>
    <texture name="grid" type="2d" builtin="checker" width="512" height="512" rgb1=".1 .2 .3" rgb2=".2 .3 .4"/>
    <material name="grid" texture="grid" texrepeat="1 1" texuniform="true" reflectance=".2"/>
  </asset>

  <worldbody>
  <body name="ground" pos="0 0 0">
  <freejoint/>

    <body name="[0-1-0]" pos="0.000000 0.000000 0.000000" >

    <geom type="cylinder" pos="0.498488 -0.038856 0.000000" axisangle="0.077712 0.996976 -0.000000 1.570796" size="0.025 0.45" material="metal" contype="1"/>
    <body name="[0-1-1]" pos="0.498488 -0.038856 0.000000" >
        <geom type="cylinder" pos="0.238422 -0.018585 0.000000" axisangle="0.077712 0.996976 -0.000000 1.570796" size="0.02 0.5" material="gray" contype="1"/>
        <joint name="Linear-0-1" type="slide" axis="0.996976 -0.077712 0.000000" range="-0.239146 0.710854"/>

    <body name="[1-2-0]" pos="0.736910 -0.057441 0.000000" >
    <joint name="Passive1-2" type="ball" pos="0.000000 0.000000 0.000000" axis="0 1 0" damping=".9"/>
    <geom type="cylinder" pos="-0.215594 0.451131 -0.000000" axisangle="-0.902262 -0.431187 0.000000 1.570796" size="0.025 0.45" material="metal" contype="1"/>
    <body name="[1-2-1]" pos="-0.215594 0.451131 -0.000000" >
        <geom type="cylinder" pos="-0.103117 0.215772 -0.000000" axisangle="-0.902262 -0.431187 0.000000 1.570796" size="0.02 0.5" material="gray" contype="1"/>
        <joint name="Linear-1-2" type="slide" axis="-0.431187 0.902262 -0.000000" range="-0.239146 0.710854"/>

    <body name="[2-3-0]" pos="-0.318710 0.666903 -0.000000" >
    <joint name="Passive2-3" type="ball" pos="0.000000 0.000000 0.000000" axis="0 1 0" damping=".9"/>
    <geom type="cylinder" pos="0.238027 -0.163329 0.408248" axisangle="0.326658 0.476054 -0.000000 0.615480" size="0.025 0.45" material="metal" contype="1"/>
    <body name="[2-3-1]" pos="0.238027 -0.163329 0.408248" >
        <geom type="cylinder" pos="0.113846 -0.078119 0.195262" axisangle="0.326658 0.476054 -0.000000 0.615480" size="0.02 0.5" material="gray" contype="1"/>
        <joint name="Linear-2-3" type="slide" axis="0.476054 -0.326658 0.816497" range="-0.239146 0.710854"/>

    <body name="[3-4-0]" pos="0.351873 -0.241448 0.603510" >
    <joint name="Passive3-4" type="ball" pos="0.000000 0.000000 0.000000" axis="0 1 0" damping=".9"/>
    <geom type="cylinder" pos="-0.498488 0.038856 -0.000000" axisangle="-0.077712 -0.996976 0.000000 1.570796" size="0.025 0.45" material="metal" contype="1"/>
    <body name="[3-4-1]" pos="-0.498488 0.038856 -0.000000" >
        <geom type="cylinder" pos="-0.238422 0.018585 -0.000000" axisangle="-0.077712 -0.996976 0.000000 1.570796" size="0.02 0.5" material="gray" contype="1"/>
        <joint name="Linear-3-4" type="slide" axis="-0.996976 0.077712 -0.000000" range="-0.239146 0.710854"/>

    <body name="[4-5-0]" pos="-0.736910 0.057441 -0.000000" >
    <joint name="Passive4-5" type="ball" pos="0.000000 0.000000 0.000000" axis="0 1 0" damping=".9"/>
    <geom type="cylinder" pos="0.215594 -0.451131 0.000000" axisangle="0.902262 0.431187 -0.000000 1.570796" size="0.025 0.45" material="metal" contype="1"/>
    <body name="[4-5-1]" pos="0.215594 -0.451131 0.000000" >
        <geom type="cylinder" pos="0.103117 -0.215772 0.000000" axisangle="0.902262 0.431187 -0.000000 1.570796" size="0.02 0.5" material="gray" contype="1"/>
        <joint name="Linear-4-5" type="slide" axis="0.431187 -0.902262 0.000000" range="-0.239146 0.710854"/>

    </body>
    </body>

    </body>
    </body>

    <body name="[3-5-0]" pos="0.351873 -0.241448 0.603510" >
    <joint name="Passive3-5" type="ball" pos="0.000000 0.000000 0.000000" axis="0 1 0" damping=".9"/>
    <geom type="cylinder" pos="-0.282894 -0.412275 -0.000000" axisangle="0.824550 -0.565789 0.000000 1.570796" size="0.025 0.45" material="metal" contype="1"/>
    <body name="[3-5-1]" pos="-0.282894 -0.412275 -0.000000" >
        <geom type="cylinder" pos="-0.135306 -0.197188 -0.000000" axisangle="0.824550 -0.565789 0.000000 1.570796" size="0.02 0.5" material="gray" contype="1"/>
        <joint name="Linear-3-5" type="slide" axis="-0.565789 -0.824550 -0.000000" range="-0.239146 0.710854"/>

    </body>
    </body>

    </body>
    </body>

    <body name="[2-4-0]" pos="-0.318710 0.666903 -0.000000" >
    <joint name="Passive2-4" type="ball" pos="0.000000 0.000000 0.000000" axis="0 1 0" damping=".9"/>
    <geom type="cylinder" pos="-0.260461 -0.124473 0.408248" axisangle="0.248946 -0.520921 0.000000 0.615480" size="0.025 0.45" material="metal" contype="1"/>
    <body name="[2-4-1]" pos="-0.260461 -0.124473 0.408248" >
        <geom type="cylinder" pos="-0.124576 -0.059534 0.195262" axisangle="0.248946 -0.520921 0.000000 0.615480" size="0.02 0.5" material="gray" contype="1"/>
        <joint name="Linear-2-4" type="slide" axis="-0.520921 -0.248946 0.816497" range="-0.239146 0.710854"/>

    </body>
    </body>

    </body>
    </body>

    <body name="[1-3-0]" pos="0.736910 -0.057441 0.000000" >
    <joint name="Passive1-3" type="ball" pos="0.000000 0.000000 0.000000" axis="0 1 0" damping=".9"/>
    <geom type="cylinder" pos="0.022434 0.287802 0.408248" axisangle="-0.575604 0.044867 0.000000 0.615480" size="0.025 0.45" material="metal" contype="1"/>
    <body name="[1-3-1]" pos="0.022434 0.287802 0.408248" >
        <geom type="cylinder" pos="0.010730 0.137653 0.195262" axisangle="-0.575604 0.044867 0.000000 0.615480" size="0.02 0.5" material="gray" contype="1"/>
        <joint name="Linear-1-3" type="slide" axis="0.044867 0.575604 0.816497" range="-0.239146 0.710854"/>

    </body>
    </body>

    <body name="[1-5-0]" pos="0.736910 -0.057441 0.000000" >
    <joint name="Passive1-5" type="ball" pos="0.000000 0.000000 0.000000" axis="0 1 0" damping=".9"/>
    <geom type="cylinder" pos="-0.260461 -0.124473 0.408248" axisangle="0.248946 -0.520921 0.000000 0.615480" size="0.025 0.45" material="metal" contype="1"/>
    <body name="[1-5-1]" pos="-0.260461 -0.124473 0.408248" >
        <geom type="cylinder" pos="-0.124576 -0.059534 0.195262" axisangle="0.248946 -0.520921 0.000000 0.615480" size="0.02 0.5" material="gray" contype="1"/>
        <joint name="Linear-1-5" type="slide" axis="-0.520921 -0.248946 0.816497" range="-0.239146 0.710854"/>

    </body>
    </body>

    </body>
    </body>

    <body name="[0-2-0]" pos="0.000000 0.000000 0.000000" >
    <joint name="Passive0-2" type="ball" pos="0.000000 0.000000 0.000000" axis="0 1 0" damping=".9"/>
    <geom type="cylinder" pos="0.282894 0.412275 0.000000" axisangle="-0.824550 0.565789 0.000000 1.570796" size="0.025 0.45" material="metal" contype="1"/>
    <body name="[0-2-1]" pos="0.282894 0.412275 0.000000" >
        <geom type="cylinder" pos="0.135306 0.197188 0.000000" axisangle="-0.824550 0.565789 0.000000 1.570796" size="0.02 0.5" material="gray" contype="1"/>
        <joint name="Linear-0-2" type="slide" axis="0.565789 0.824550 0.000000" range="-0.239146 0.710854"/>

    </body>
    </body>

    <body name="[0-4-0]" pos="0.000000 0.000000 0.000000" >
    <joint name="Passive0-4" type="ball" pos="0.000000 0.000000 0.000000" axis="0 1 0" damping=".9"/>
    <geom type="cylinder" pos="0.022434 0.287802 0.408248" axisangle="-0.575604 0.044867 0.000000 0.615480" size="0.025 0.45" material="metal" contype="1"/>
    <body name="[0-4-1]" pos="0.022434 0.287802 0.408248" >
        <geom type="cylinder" pos="0.010730 0.137653 0.195262" axisangle="-0.575604 0.044867 0.000000 0.615480" size="0.02 0.5" material="gray" contype="1"/>
        <joint name="Linear-0-4" type="slide" axis="0.044867 0.575604 0.816497" range="-0.239146 0.710854"/>

    </body>
    </body>

    <body name="[0-5-0]" pos="0.000000 0.000000 0.000000" >
    <joint name="Passive0-5" type="ball" pos="0.000000 0.000000 0.000000" axis="0 1 0" damping=".9"/>
    <geom type="cylinder" pos="0.238027 -0.163329 0.408248" axisangle="0.326658 0.476054 -0.000000 0.615480" size="0.025 0.45" material="metal" contype="1"/>
    <body name="[0-5-1]" pos="0.238027 -0.163329 0.408248" >
        <geom type="cylinder" pos="0.113846 -0.078119 0.195262" axisangle="0.326658 0.476054 -0.000000 0.615480" size="0.02 0.5" material="gray" contype="1"/>
        <joint name="Linear-0-5" type="slide" axis="0.476054 -0.326658 0.816497" range="-0.239146 0.710854"/>

    </body>
    </body>
    </body> </worldbody> <equality>
<connect name="kinematic_link_0-0" active="true" body1="[0-2-1]" body2="[1-2-1]" anchor=" 0.418200 0.609463 0.000000" />
<connect name="kinematic_link_1-0" active="true" body1="[0-4-1]" body2="[2-4-1]" anchor=" 0.033163 0.425455 0.603510" />
<connect name="kinematic_link_1-1" active="true" body1="[0-4-1]" body2="[3-4-1]" anchor=" 0.033163 0.425455 0.603510" />
<connect name="kinematic_link_2-0" active="true" body1="[0-5-1]" body2="[1-5-1]" anchor=" 0.351873 -0.241448 0.603510" />
<connect name="kinematic_link_2-1" active="true" body1="[0-5-1]" body2="[3-5-1]" anchor=" 0.351873 -0.241448 0.603510" />
<connect name="kinematic_link_2-2" active="true" body1="[0-5-1]" body2="[4-5-1]" anchor=" 0.351873 -0.241448 0.603510" />
<connect name="kinematic_link_3-0" active="true" body1="[1-3-1]" body2="[2-3-1]" anchor=" 0.033163 0.425455 0.603510" />
<connect name="kinematic_link_4-0" active="true" body1="[1-5-1]" body2="[0-5-1]" anchor=" -0.385037 -0.184007 0.603510" />
<connect name="kinematic_link_4-1" active="true" body1="[1-5-1]" body2="[3-5-1]" anchor=" -0.385037 -0.184007 0.603510" />
<connect name="kinematic_link_4-2" active="true" body1="[1-5-1]" body2="[4-5-1]" anchor=" -0.385037 -0.184007 0.603510" />
<connect name="kinematic_link_5-0" active="true" body1="[2-4-1]" body2="[0-4-1]" anchor=" -0.385037 -0.184007 0.603510" />
<connect name="kinematic_link_5-1" active="true" body1="[2-4-1]" body2="[3-4-1]" anchor=" -0.385037 -0.184007 0.603510" />
<connect name="kinematic_link_6-0" active="true" body1="[3-5-1]" body2="[0-5-1]" anchor=" -0.418200 -0.609463 -0.000000" />
<connect name="kinematic_link_6-1" active="true" body1="[3-5-1]" body2="[1-5-1]" anchor=" -0.418200 -0.609463 -0.000000" />
<connect name="kinematic_link_6-2" active="true" body1="[3-5-1]" body2="[4-5-1]" anchor=" -0.418200 -0.609463 -0.000000" />
<connect name="kinematic_link_7-0" active="true" body1="[4-5-1]" body2="[0-5-1]" anchor=" 0.318710 -0.666903 0.000000" />
<connect name="kinematic_link_7-1" active="true" body1="[4-5-1]" body2="[1-5-1]" anchor=" 0.318710 -0.666903 0.000000" />
<connect name="kinematic_link_7-2" active="true" body1="[4-5-1]" body2="[3-5-1]" anchor=" 0.318710 -0.666903 0.000000" /></equality><actuator>

<intvelocity name="Member-1-2" joint="Linear-1-2" kp="18000"  kv="10000" inheritrange="1" />
<intvelocity name="Member-1-3" joint="Linear-1-3" kp="18000"  kv="10000" inheritrange="1" />
<intvelocity name="Member-1-5" joint="Linear-1-5" kp="18000"  kv="10000" inheritrange="1" />
<intvelocity name="Member-0-1" joint="Linear-0-1" kp="18000"  kv="10000" inheritrange="1" />
<intvelocity name="Member-0-2" joint="Linear-0-2" kp="18000"  kv="10000" inheritrange="1" />
<intvelocity name="Member-0-4" joint="Linear-0-4" kp="18000"  kv="10000" inheritrange="1" />
<intvelocity name="Member-0-5" joint="Linear-0-5" kp="18000"  kv="10000" inheritrange="1" />
<intvelocity name="Member-2-3" joint="Linear-2-3" kp="18000"  kv="10000" inheritrange="1" />
<intvelocity name="Member-2-4" joint="Linear-2-4" kp="18000"  kv="10000" inheritrange="1" />
<intvelocity name="Member-3-4" joint="Linear-3-4" kp="18000"  kv="10000" inheritrange="1" />
<intvelocity name="Member-3-5" joint="Linear-3-5" kp="18000"  kv="10000" inheritrange="1" />
<intvelocity name="Member-4-5" joint="Linear-4-5" kp="18000"  kv="10000" inheritrange="1" /></actuator>
</mujoco>