<mujoco model="3-tet">
  <compiler angle="radian" meshdir="assets" autolimits="true"/>
  <option gravity="0 0 -9.81" timestep="0.002" integrator="implicit"/>

  <option cone="elliptic" impratio="10"/>

  <asset>
    <material name="metal" rgba="0.58 0.58 0.58 1"/>
    <material name="gray" rgba="0.4627 0.4627 0.4627 1"/>
    <material name="red" rgba="0.9 0.1 0.1 1"/>
    <texture name="grid" type="2d" builtin="checker" width="512" height="512" rgb1=".1 .2 .3" rgb2=".2 .3 .4"/>
    <material name="grid" texture="grid" texrepeat="1 1" texuniform="true" reflectance=".2"/>
  </asset>

  <worldbody>
  <body name="ground" pos="0 0 0">
  <freejoint/>

    <body name="[0-1-0]" pos="0.000000 0.000000 0.000000" >

    <geom type="cylinder" pos="0.338899 0.367624 0.000000" axisangle="-0.735248 0.677798 0.000000 1.570796" size="0.025 0.45" material="metal" contype="1"/>
    <body name="[0-1-1]" pos="0.338899 0.367624 0.000000" >
        <geom type="cylinder" pos="0.181983 0.197407 0.000000" axisangle="-0.735248 0.677798 0.000000 1.570796" size="0.02 0.5" material="gray" contype="1"/>
        <joint name="Linear-0-1" type="slide" axis="0.677798 0.735248 0.000000" range="-0.268491 0.681509"/>

    <body name="[1-2-0]" pos="0.520882 0.565031 0.000000" >
    <joint name="Passive1-2" type="ball" pos="0.000000 0.000000 0.000000" axis="0 1 0" damping=".9"/>
    <geom type="cylinder" pos="-0.482470 0.131235 -0.000000" axisangle="-0.262469 -0.964940 0.000000 1.570796" size="0.025 0.45" material="metal" contype="1"/>
    <body name="[1-2-1]" pos="-0.482470 0.131235 0.000000" >
        <geom type="cylinder" pos="-0.163720 0.044533 -0.000000" axisangle="-0.262469 -0.964940 0.000000 1.570796" size="0.02 0.5" material="gray" contype="1"/>
        <joint name="Linear-1-2" type="slide" axis="-0.964940 0.262469 0.000000" range="-0.169668 0.780332"/>

    <body name="[2-3-0]" pos="-0.646190 0.175767 0.000000" >
    <joint name="Passive2-3" type="ball" pos="0.000000 0.000000 0.000000" axis="0 1 0" damping=".9"/>
    <geom type="cylinder" pos="0.159468 -0.272782 0.387505" axisangle="0.545565 0.318935 -0.000000 0.684067" size="0.025 0.45" material="metal" contype="1"/>
    <body name="[2-3-1]" pos="0.159468 -0.272782 0.387505" >
        <geom type="cylinder" pos="0.094706 -0.162002 0.230135" axisangle="0.545565 0.318935 -0.000000 0.684067" size="0.02 0.5" material="gray" contype="1"/>
        <joint name="Linear-2-3" type="slide" axis="0.318935 -0.545565 0.775009" range="-0.296944 0.653056"/>

    <body name="[3-4-0]" pos="0.254174 -0.434785 0.617639" >
    <joint name="Passive3-4" type="ball" pos="0.000000 0.000000 0.000000" axis="0 1 0" damping=".9"/>
    <geom type="cylinder" pos="0.131218 0.482475 -0.000005" axisangle="-0.964949 0.262436 0.000000 1.570807" size="0.025 0.45" material="metal" contype="1"/>
    <body name="[3-4-1]" pos="0.131218 0.482475 -0.000005" >
        <geom type="cylinder" pos="0.038910 0.143066 -0.000002" axisangle="-0.964949 0.262436 0.000000 1.570807" size="0.02 0.5" material="gray" contype="1"/>
        <joint name="Linear-3-4" type="slide" axis="0.262436 0.964949 -0.000010" range="-0.148263 0.801737"/>

    <body name="[4-5-0]" pos="0.170128 0.625541 -0.000007" >
    <joint name="Passive4-5" type="ball" pos="0.000000 0.000000 0.000000" axis="0 1 0" damping=".9"/>
    <geom type="cylinder" pos="0.063153 0.232129 -0.438324" axisangle="-0.464258 0.126307 0.000000 2.639646" size="0.025 0.45" material="metal" contype="1"/>
    <body name="[4-5-1]" pos="0.063153 0.232129 -0.438324" >
        <geom type="cylinder" pos="0.018512 0.068043 -0.128484" axisangle="-0.464258 0.126307 0.000000 2.639646" size="0.02 0.5" material="gray" contype="1"/>
        <joint name="Linear-4-5" type="slide" axis="0.126307 0.464258 -0.876648" range="-0.146563 0.803437"/>

    </body>
    </body>

    </body>
    </body>

    </body>
    </body>

    <body name="[2-4-0]" pos="-0.646190 0.175767 0.000000" >
    <joint name="Passive2-4" type="ball" pos="0.000000 0.000000 0.000000" axis="0 1 0" damping=".9"/>
    <geom type="cylinder" pos="0.275660 0.154391 0.387524" axisangle="-0.308782 0.551320 0.000000 0.684005" size="0.025 0.45" material="metal" contype="1"/>
    <body name="[2-4-1]" pos="0.275660 0.154391 0.387524" >
        <geom type="cylinder" pos="0.163667 0.091666 0.230084" axisangle="-0.308782 0.551320 0.000000 0.684005" size="0.02 0.5" material="gray" contype="1"/>
        <joint name="Linear-2-4" type="slide" axis="0.551320 0.308782 0.775048" range="-0.296864 0.653136"/>

    </body>
    </body>

    <body name="[2-5-0]" pos="-0.646190 0.175767 0.000000" >
    <joint name="Passive2-5" type="ball" pos="0.000000 0.000000 0.000000" axis="0 1 0" damping=".9"/>
    <geom type="cylinder" pos="0.338886 0.367636 -0.000000" axisangle="-0.735272 0.677772 0.000000 1.570796" size="0.025 0.45" material="metal" contype="1"/>
    <body name="[2-5-1]" pos="0.338886 0.367636 -0.000000" >
        <geom type="cylinder" pos="0.182034 0.197477 -0.000000" axisangle="-0.735272 0.677772 0.000000 1.570796" size="0.02 0.5" material="gray" contype="1"/>
        <joint name="Linear-2-5" type="slide" axis="0.677772 0.735272 -0.000000" range="-0.268577 0.681423"/>

    </body>
    </body>

    </body>
    </body>

    <body name="[1-3-0]" pos="0.520882 0.565031 0.000000" >
    <joint name="Passive1-3" type="ball" pos="0.000000 0.000000 0.000000" axis="0 1 0" damping=".9"/>
    <geom type="cylinder" pos="-0.275659 -0.154429 0.387510" axisangle="0.308857 -0.551318 0.000000 0.684050" size="0.025 0.45" material="metal" contype="1"/>
    <body name="[1-3-1]" pos="-0.275659 -0.154429 0.387510" >
        <geom type="cylinder" pos="-0.163701 -0.091708 0.230124" axisangle="0.308857 -0.551318 0.000000 0.684050" size="0.02 0.5" material="gray" contype="1"/>
        <joint name="Linear-1-3" type="slide" axis="-0.551318 -0.308857 0.775020" range="-0.296927 0.653073"/>

    </body>
    </body>

    <body name="[1-4-0]" pos="0.520882 0.565031 0.000000" >
    <joint name="Passive1-4" type="ball" pos="0.000000 0.000000 0.000000" axis="0 1 0" damping=".9"/>
    <geom type="cylinder" pos="-0.159488 0.272751 0.387519" axisangle="-0.545501 -0.318975 0.000000 0.684022" size="0.025 0.45" material="metal" contype="1"/>
    <body name="[1-4-1]" pos="-0.159488 0.272751 0.387519" >
        <geom type="cylinder" pos="-0.094698 0.161949 0.230094" axisangle="-0.545501 -0.318975 0.000000 0.684022" size="0.02 0.5" material="gray" contype="1"/>
        <joint name="Linear-1-4" type="slide" axis="-0.318975 0.545501 0.775038" range="-0.296882 0.653118"/>

    </body>
    </body>

    <body name="[1-5-0]" pos="0.520882 0.565031 0.000000" >
    <joint name="Passive1-5" type="ball" pos="0.000000 0.000000 0.000000" axis="0 1 0" damping=".9"/>
    <geom type="cylinder" pos="-0.105968 0.488642 -0.000000" axisangle="-0.977284 -0.211935 0.000000 1.570796" size="0.025 0.45" material="metal" contype="1"/>
    <body name="[1-5-1]" pos="-0.105968 0.488642 -0.000000" >
        <geom type="cylinder" pos="-0.056919 0.262468 -0.000000" axisangle="-0.977284 -0.211935 0.000000 1.570796" size="0.02 0.5" material="gray" contype="1"/>
        <joint name="Linear-1-5" type="slide" axis="-0.211935 0.977284 -0.000000" range="-0.268568 0.681432"/>

    </body>
    </body>

    </body>
    </body>

    <body name="[0-2-0]" pos="0.000000 0.000000 0.000000" >
    <joint name="Passive0-2" type="ball" pos="0.000000 0.000000 0.000000" axis="0 1 0" damping=".9"/>
    <geom type="cylinder" pos="-0.105985 0.488638 0.000000" axisangle="-0.977276 -0.211969 0.000000 1.570796" size="0.025 0.45" material="metal" contype="1"/>
    <body name="[0-2-1]" pos="-0.105985 0.488638 0.000000" >
        <geom type="cylinder" pos="-0.056910 0.262381 0.000000" axisangle="-0.977276 -0.211969 0.000000 1.570796" size="0.02 0.5" material="gray" contype="1"/>
        <joint name="Linear-0-2" type="slide" axis="-0.211969 0.977276 0.000000" range="-0.268482 0.681518"/>

    </body>
    </body>

    <body name="[0-3-0]" pos="0.000000 0.000000 0.000000" >
    <joint name="Passive0-3" type="ball" pos="0.000000 0.000000 0.000000" axis="0 1 0" damping=".9"/>
    <geom type="cylinder" pos="0.063134 0.232056 0.438365" axisangle="-0.464112 0.126268 0.000000 0.501774" size="0.025 0.45" material="metal" contype="1"/>
    <body name="[0-3-1]" pos="0.063134 0.232056 0.438365" >
        <geom type="cylinder" pos="0.018494 0.067978 0.128413" axisangle="-0.464112 0.126268 0.000000 0.501774" size="0.02 0.5" material="gray" contype="1"/>
        <joint name="Linear-0-3" type="slide" axis="0.126268 0.464112 0.876731" range="-0.146468 0.803532"/>

    </body>
    </body>
    </body> </worldbody> <equality>
<connect name="kinematic_link_0-0" active="true" body1="[0-2-1]" body2="[1-2-1]" anchor=" -0.162895 0.751019 0.000000" />
<connect name="kinematic_link_1-0" active="true" body1="[0-3-1]" body2="[1-3-1]" anchor=" 0.081628 0.300034 0.566779" />
<connect name="kinematic_link_1-1" active="true" body1="[0-3-1]" body2="[2-3-1]" anchor=" 0.081628 0.300034 0.566779" />
<connect name="kinematic_link_2-0" active="true" body1="[1-3-1]" body2="[0-3-1]" anchor=" -0.439360 -0.246137 0.617634" />
<connect name="kinematic_link_2-1" active="true" body1="[1-3-1]" body2="[2-3-1]" anchor=" -0.439360 -0.246137 0.617634" />
<connect name="kinematic_link_3-0" active="true" body1="[1-4-1]" body2="[2-4-1]" anchor=" -0.254185 0.434700 0.617613" />
<connect name="kinematic_link_3-1" active="true" body1="[1-4-1]" body2="[3-4-1]" anchor=" -0.254185 0.434700 0.617613" />
<connect name="kinematic_link_4-0" active="true" body1="[1-5-1]" body2="[2-5-1]" anchor=" -0.162887 0.751109 -0.000000" />
<connect name="kinematic_link_4-1" active="true" body1="[1-5-1]" body2="[4-5-1]" anchor=" -0.162887 0.751109 -0.000000" />
<connect name="kinematic_link_5-0" active="true" body1="[2-4-1]" body2="[1-4-1]" anchor=" 0.439327 0.246057 0.617608" />
<connect name="kinematic_link_6-0" active="true" body1="[2-5-1]" body2="[1-5-1]" anchor=" 0.520920 0.565113 -0.000000" />
<connect name="kinematic_link_6-1" active="true" body1="[2-5-1]" body2="[4-5-1]" anchor=" 0.520920 0.565113 -0.000000" />
<connect name="kinematic_link_7-0" active="true" body1="[4-5-1]" body2="[1-5-1]" anchor=" 0.081665 0.300172 -0.566808" />
<connect name="kinematic_link_7-1" active="true" body1="[4-5-1]" body2="[2-5-1]" anchor=" 0.081665 0.300172 -0.566808" /></equality><actuator>

<intvelocity name="Member-1-2" joint="Linear-1-2" kp="18000"  kv="10000" inheritrange="1" />
<intvelocity name="Member-1-3" joint="Linear-1-3" kp="18000"  kv="10000" inheritrange="1" />
<intvelocity name="Member-1-4" joint="Linear-1-4" kp="18000"  kv="10000" inheritrange="1" />
<intvelocity name="Member-1-5" joint="Linear-1-5" kp="18000"  kv="10000" inheritrange="1" />
<intvelocity name="Member-0-1" joint="Linear-0-1" kp="18000"  kv="10000" inheritrange="1" />
<intvelocity name="Member-0-2" joint="Linear-0-2" kp="18000"  kv="10000" inheritrange="1" />
<intvelocity name="Member-0-3" joint="Linear-0-3" kp="18000"  kv="10000" inheritrange="1" />
<intvelocity name="Member-2-3" joint="Linear-2-3" kp="18000"  kv="10000" inheritrange="1" />
<intvelocity name="Member-2-4" joint="Linear-2-4" kp="18000"  kv="10000" inheritrange="1" />
<intvelocity name="Member-2-5" joint="Linear-2-5" kp="18000"  kv="10000" inheritrange="1" />
<intvelocity name="Member-3-4" joint="Linear-3-4" kp="18000"  kv="10000" inheritrange="1" />
<intvelocity name="Member-4-5" joint="Linear-4-5" kp="18000"  kv="10000" inheritrange="1" /></actuator>
</mujoco>