<mujoco model="1-tet">
  <compiler angle="radian" meshdir="assets" autolimits="true"/>
  <option gravity="0 0 -9.81" timestep="0.002" integrator="implicit"/>

  <option cone="elliptic" impratio="10"/>

  <asset>
    <material name="metal" rgba="0.58 0.58 0.58 1"/>
    <material name="gray" rgba="0.4627 0.4627 0.4627 1"/>
    <material name="red" rgba="0.9 0.1 0.1 1"/>
    <texture name="grid" type="2d" builtin="checker" width="512" height="512" rgb1=".1 .2 .3" rgb2=".2 .3 .4"/>
    <material name="grid" texture="grid" texrepeat="1 1" texuniform="true" reflectance=".2"/>
  </asset>

  <worldbody>
  <body name="ground" pos="0 0 0">
  <freejoint/>

    <body name="[0-1-0]" pos="0.000000 0.000000 0.000000" >
    <geom type="sphere" name="(0)" pos="0.000000 0.000000 0.000000" size="0.05" material="red"contype="1" mass="10"/>

    <geom type="cylinder" pos="0.499434 -0.023774 -0.000000" axisangle="0.047548 0.998869 -0.000000 1.570796" size="0.025 0.45" material="metal" contype="1"/>
    <body name="[0-1-1]" pos="0.499434 -0.023774 -0.000000" >
        <geom type="cylinder" pos="0.227634 -0.010836 -0.000000" axisangle="0.047548 0.998869 -0.000000 1.570796" size="0.02 0.5" material="gray" contype="1"/>
        <joint name="Linear-0-1" type="slide" axis="0.998869 -0.047548 -0.000000" range="-0.227892 0.722108"/>


    <body name="[1-2-0]" pos="0.727068 -0.034610 -0.000000" >
    <geom type="sphere" name="(1)" pos="0.000000 0.000000 0.000000" size="0.05" material="red"contype="1" mass="10"/>
    <joint name="Passive1-2" type="ball" pos="0.000000 0.000000 0.000000" axis="0 1 0" damping=".9"/>
    <geom type="cylinder" pos="-0.229128 0.444410 0.000000" axisangle="-0.888820 -0.458257 0.000000 1.570796" size="0.025 0.45" material="metal" contype="1"/>
    <body name="[1-2-1]" pos="-0.229128 0.444410 0.000000" >
        <geom type="cylinder" pos="-0.104433 0.202555 0.000000" axisangle="-0.888820 -0.458257 0.000000 1.570796" size="0.02 0.5" material="gray" contype="1"/>
        <joint name="Linear-1-2" type="slide" axis="-0.458257 0.888820 0.000000" range="-0.227892 0.722108"/>


    <body name="[2-3-0]" pos="-0.333561 0.646965 0.000000" >
    <geom type="sphere" name="(2)" pos="0.000000 0.000000 0.000000" size="0.05" material="red"contype="1" mass="10"/>
    <joint name="Passive2-3" type="ball" pos="0.000000 0.000000 0.000000" axis="0 1 0" damping=".9"/>
    <geom type="cylinder" pos="-0.013726 -0.288349 0.408248" axisangle="0.576697 -0.027452 0.000000 0.615480" size="0.025 0.45" material="metal" contype="1"/>
    <body name="[2-3-1]" pos="-0.013726 -0.288349 0.408248" >
        <geom type="cylinder" pos="-0.006256 -0.131424 0.186073" axisangle="0.576697 -0.027452 0.000000 0.615480" size="0.02 0.5" material="gray" contype="1"/>
        <joint name="Linear-2-3" type="slide" axis="-0.027452 -0.576697 0.816497" range="-0.227892 0.722108"/>
        <geom type="sphere" name="(3)" pos="-0.019982 -0.419773 0.594321" size="0.05" material="red"contype="1" mass="10"/>

    </body>
    </body>

    </body>
    </body>

    <body name="[1-3-0]" pos="0.727068 -0.034610 -0.000000" >

    <joint name="Passive1-3" type="ball" pos="0.000000 0.000000 0.000000" axis="0 1 0" damping=".9"/>
    <geom type="cylinder" pos="-0.242854 0.156061 0.408248" axisangle="-0.312123 -0.485708 0.000000 0.615480" size="0.025 0.45" material="metal" contype="1"/>
    <body name="[1-3-1]" pos="-0.242854 0.156061 0.408248" >
        <geom type="cylinder" pos="-0.110689 0.071130 0.186073" axisangle="-0.312123 -0.485708 0.000000 0.615480" size="0.02 0.5" material="gray" contype="1"/>
        <joint name="Linear-1-3" type="slide" axis="-0.485708 0.312123 0.816497" range="-0.227892 0.722108"/>


    </body>
    </body>

    </body>
    </body>

    <body name="[0-2-0]" pos="0.000000 0.000000 0.000000" >

    <joint name="Passive0-2" type="ball" pos="0.000000 0.000000 0.000000" axis="0 1 0" damping=".9"/>
    <geom type="cylinder" pos="0.270306 0.420636 -0.000000" axisangle="-0.841272 0.540612 0.000000 1.570796" size="0.025 0.45" material="metal" contype="1"/>
    <body name="[0-2-1]" pos="0.270306 0.420636 -0.000000" >
        <geom type="cylinder" pos="0.123201 0.191719 -0.000000" axisangle="-0.841272 0.540612 0.000000 1.570796" size="0.02 0.5" material="gray" contype="1"/>
        <joint name="Linear-0-2" type="slide" axis="0.540612 0.841272 -0.000000" range="-0.227892 0.722108"/>


    </body>
    </body>

    <body name="[0-3-0]" pos="0.000000 0.000000 0.000000" >

    <joint name="Passive0-3" type="ball" pos="0.000000 0.000000 0.000000" axis="0 1 0" damping=".9"/>
    <geom type="cylinder" pos="0.256580 0.132287 0.408248" axisangle="-0.264575 0.513160 0.000000 0.615480" size="0.025 0.45" material="metal" contype="1"/>
    <body name="[0-3-1]" pos="0.256580 0.132287 0.408248" >
        <geom type="cylinder" pos="0.116945 0.060294 0.186073" axisangle="-0.264575 0.513160 0.000000 0.615480" size="0.02 0.5" material="gray" contype="1"/>
        <joint name="Linear-0-3" type="slide" axis="0.513160 0.264575 0.816497" range="-0.227892 0.722108"/>


    </body>
    </body>
    </body> </worldbody> <equality>
<connect name="kinematic_link_0-0" active="true" body1="[0-2-1]" body2="[1-2-1]" anchor=" 0.393507 0.612355 -0.000000" />
<connect name="kinematic_link_1-0" active="true" body1="[0-3-1]" body2="[1-3-1]" anchor=" 0.373525 0.192582 0.594321" />
<connect name="kinematic_link_1-1" active="true" body1="[0-3-1]" body2="[2-3-1]" anchor=" 0.373525 0.192582 0.594321" />
<connect name="kinematic_link_2-0" active="true" body1="[1-3-1]" body2="[0-3-1]" anchor=" -0.353543 0.227191 0.594321" />
<connect name="kinematic_link_2-1" active="true" body1="[1-3-1]" body2="[2-3-1]" anchor=" -0.353543 0.227191 0.594321" />
<connect name="kinematic_link_3-0" active="true" body1="[2-3-1]" body2="[0-3-1]" anchor=" -0.019982 -0.419773 0.594321" />
<connect name="kinematic_link_3-1" active="true" body1="[2-3-1]" body2="[1-3-1]" anchor=" -0.019982 -0.419773 0.594321" /></equality><actuator>

<motor name="Member-0-1" joint="Linear-0-1"   ctrllimited="true" ctrlrange="-1.0 1.0" gear="300" />
<motor name="Member-0-2" joint="Linear-0-2"   ctrllimited="true" ctrlrange="-1.0 1.0" gear="300" />
<motor name="Member-0-3" joint="Linear-0-3"   ctrllimited="true" ctrlrange="-1.0 1.0" gear="300" />
<motor name="Member-0-4" joint="Linear-0-1"    ctrllimited="true" ctrlrange="-1.0 1.0" gear="1" />
<motor name="Member-0-5" joint="Linear-0-1"    ctrllimited="true" ctrlrange="-1.0 1.0" gear="1" />
<motor name="Member-1-2" joint="Linear-1-2"   ctrllimited="true" ctrlrange="-1.0 1.0" gear="300" />
<motor name="Member-1-3" joint="Linear-1-3"   ctrllimited="true" ctrlrange="-1.0 1.0" gear="300" />
<motor name="Member-1-4" joint="Linear-0-1"    ctrllimited="true" ctrlrange="-1.0 1.0" gear="1" />
<motor name="Member-1-5" joint="Linear-0-1"    ctrllimited="true" ctrlrange="-1.0 1.0" gear="1" />
<motor name="Member-2-3" joint="Linear-2-3"   ctrllimited="true" ctrlrange="-1.0 1.0" gear="300" />
<motor name="Member-2-4" joint="Linear-0-1"    ctrllimited="true" ctrlrange="-1.0 1.0" gear="1" />
<motor name="Member-2-5" joint="Linear-0-1"    ctrllimited="true" ctrlrange="-1.0 1.0" gear="1" />
<motor name="Member-3-4" joint="Linear-0-1"    ctrllimited="true" ctrlrange="-1.0 1.0" gear="1" />
<motor name="Member-3-5" joint="Linear-0-1"    ctrllimited="true" ctrlrange="-1.0 1.0" gear="1" />
<motor name="Member-4-5" joint="Linear-0-1"    ctrllimited="true" ctrlrange="-1.0 1.0" gear="1" />
</actuator>
</mujoco>
