<mujoco model="1-tet-1">
  <compiler angle="radian" meshdir="assets" autolimits="true"/>
  <option gravity="0 0 -9.81" timestep="0.002" integrator="implicit"/>

  <option cone="elliptic" impratio="10"/>

  <asset>
    <material name="metal" rgba="0.58 0.58 0.58 1"/>
    <material name="gray" rgba="0.4627 0.4627 0.4627 1"/>
    <material name="red" rgba="0.9 0.1 0.1 1"/>
    <texture name="grid" type="2d" builtin="checker" width="512" height="512" rgb1=".1 .2 .3" rgb2=".2 .3 .4"/>
    <material name="grid" texture="grid" texrepeat="1 1" texuniform="true" reflectance=".2"/>
  </asset>

  <worldbody>
  <body name="ground" pos="0 0 0">
  <freejoint/>

    <body name="[0-1-0]" pos="0.000000 0.000000 0.000000" >
    <geom type="sphere" name="(0)" pos="0.000000 0.000000 0.000000" size="0.05" material="red"contype="1" mass="10"/>

    <geom type="cylinder" pos="0.330611 0.375095 -0.000000" axisangle="-0.750191 0.661221 0.000000 1.570796" size="0.025 0.45" material="metal" contype="1"/>
    <body name="[0-1-1]" pos="0.330611 0.375095 -0.000000" >
        <geom type="cylinder" pos="0.155692 0.176640 -0.000000" axisangle="-0.750191 0.661221 0.000000 1.570796" size="0.02 0.5" material="gray" contype="1"/>
        <joint name="Linear-0-1" type="slide" axis="0.661221 0.750191 -0.000000" range="-0.235460 0.714540"/>


    <body name="[1-2-0]" pos="0.486302 0.551736 -0.000000" >
    <geom type="sphere" name="(1)" pos="0.000000 0.000000 0.000000" size="0.05" material="red"contype="1" mass="10"/>
    <joint name="Passive1-2" type="ball" pos="0.000000 0.000000 0.000000" axis="0 1 0" damping=".9"/>
    <geom type="cylinder" pos="-0.490148 0.098770 0.000000" axisangle="-0.197539 -0.980295 0.000000 1.570796" size="0.025 0.45" material="metal" contype="1"/>
    <body name="[1-2-1]" pos="-0.490148 0.098770 0.000000" >
        <geom type="cylinder" pos="-0.230821 0.046513 0.000000" axisangle="-0.197539 -0.980295 0.000000 1.570796" size="0.02 0.5" material="gray" contype="1"/>
        <joint name="Linear-1-2" type="slide" axis="-0.980295 0.197539 0.000000" range="-0.235460 0.714540"/>


    <body name="[2-3-0]" pos="-0.720968 0.145282 0.000000" >
    <geom type="sphere" name="(2)" pos="0.000000 0.000000 0.000000" size="0.05" material="red"contype="1" mass="10"/>
    <joint name="Passive2-3" type="ball" pos="0.000000 0.000000 0.000000" axis="0 1 0" damping=".9"/>
    <geom type="cylinder" pos="0.216561 -0.190878 0.408248" axisangle="0.381756 0.433123 -0.000000 0.615480" size="0.025 0.45" material="metal" contype="1"/>
    <body name="[2-3-1]" pos="0.216561 -0.190878 0.408248" >
        <geom type="cylinder" pos="0.101983 -0.089889 0.192253" axisangle="0.381756 0.433123 -0.000000 0.615480" size="0.02 0.5" material="gray" contype="1"/>
        <joint name="Linear-2-3" type="slide" axis="0.433123 -0.381756 0.816497" range="-0.235460 0.714540"/>
        <geom type="sphere" name="(3)" pos="0.318545 -0.280767 0.600501" size="0.05" material="red"contype="1" mass="10"/>

    </body>
    </body>

    <body name="[2-4-0]" pos="-0.720968 0.145282 0.000000" >

    <joint name="Passive2-4" type="ball" pos="0.000000 0.000000 0.000000" axis="0 1 0" damping=".9"/>
    <geom type="cylinder" pos="0.245417 -0.047683 0.433009" axisangle="0.095367 0.490833 -0.000000 0.523613" size="0.025 0.45" material="metal" contype="1"/>
    <body name="[2-4-1]" pos="0.245417 -0.047683 0.433009" >
        <geom type="cylinder" pos="0.115572 -0.022455 0.203913" axisangle="0.095367 0.490833 -0.000000 0.523613" size="0.02 0.5" material="gray" contype="1"/>
        <joint name="Linear-2-4" type="slide" axis="0.490833 -0.095367 0.866018" range="-0.235460 0.714540"/>
        <geom type="sphere" name="(4)" pos="0.360988 -0.070139 0.636922" size="0.05" material="red"contype="1" mass="10"/>

    </body>
    </body>

    </body>
    </body>

    <body name="[1-3-0]" pos="0.486302 0.551736 -0.000000" >

    <joint name="Passive1-3" type="ball" pos="0.000000 0.000000 0.000000" axis="0 1 0" damping=".9"/>
    <geom type="cylinder" pos="-0.273586 -0.092109 0.408248" axisangle="0.184217 -0.547172 0.000000 0.615480" size="0.025 0.45" material="metal" contype="1"/>
    <body name="[1-3-1]" pos="-0.273586 -0.092109 0.408248" >
        <geom type="cylinder" pos="-0.128837 -0.043376 0.192253" axisangle="0.184217 -0.547172 0.000000 0.615480" size="0.02 0.5" material="gray" contype="1"/>
        <joint name="Linear-1-3" type="slide" axis="-0.547172 -0.184217 0.816497" range="-0.235460 0.714540"/>


    </body>
    </body>

    <body name="[1-4-0]" pos="0.486302 0.551736 -0.000000" >

    <joint name="Passive1-4" type="ball" pos="0.000000 0.000000 0.000000" axis="0 1 0" damping=".9"/>
    <geom type="cylinder" pos="-0.244731 0.051086 0.433009" axisangle="-0.102172 -0.489462 0.000000 0.523613" size="0.025 0.45" material="metal" contype="1"/>
    <body name="[1-4-1]" pos="-0.244731 0.051086 0.433009" >
        <geom type="cylinder" pos="-0.115249 0.024058 0.203913" axisangle="-0.102172 -0.489462 0.000000 0.523613" size="0.02 0.5" material="gray" contype="1"/>
        <joint name="Linear-1-4" type="slide" axis="-0.489462 0.102172 0.866018" range="-0.235460 0.714540"/>


    </body>
    </body>

    </body>
    </body>

    <body name="[0-2-0]" pos="0.000000 0.000000 0.000000" >

    <joint name="Passive0-2" type="ball" pos="0.000000 0.000000 0.000000" axis="0 1 0" damping=".9"/>
    <geom type="cylinder" pos="-0.159537 0.473865 0.000000" axisangle="-0.947730 -0.319074 0.000000 1.570796" size="0.025 0.45" material="metal" contype="1"/>
    <body name="[0-2-1]" pos="-0.159537 0.473865 0.000000" >
        <geom type="cylinder" pos="-0.075129 0.223153 0.000000" axisangle="-0.947730 -0.319074 0.000000 1.570796" size="0.02 0.5" material="gray" contype="1"/>
        <joint name="Linear-0-2" type="slide" axis="-0.319074 0.947730 0.000000" range="-0.235460 0.714540"/>


    </body>
    </body>

    <body name="[0-3-0]" pos="0.000000 0.000000 0.000000" >

    <joint name="Passive0-3" type="ball" pos="0.000000 0.000000 0.000000" axis="0 1 0" damping=".9"/>
    <geom type="cylinder" pos="0.057025 0.282987 0.408248" axisangle="-0.565974 0.114049 0.000000 0.615480" size="0.025 0.45" material="metal" contype="1"/>
    <body name="[0-3-1]" pos="0.057025 0.282987 0.408248" >
        <geom type="cylinder" pos="0.026854 0.133264 0.192253" axisangle="-0.565974 0.114049 0.000000 0.615480" size="0.02 0.5" material="gray" contype="1"/>
        <joint name="Linear-0-3" type="slide" axis="0.114049 0.565974 0.816497" range="-0.235460 0.714540"/>


    </body>
    </body>
    </body> </worldbody> <equality>
<connect name="kinematic_link_0-0" active="true" body1="[0-2-1]" body2="[1-2-1]" anchor=" -0.234666 0.697018 0.000000" />
<connect name="kinematic_link_1-0" active="true" body1="[0-3-1]" body2="[1-3-1]" anchor=" 0.083879 0.416251 0.600501" />
<connect name="kinematic_link_1-1" active="true" body1="[0-3-1]" body2="[2-3-1]" anchor=" 0.083879 0.416251 0.600501" />
<connect name="kinematic_link_2-0" active="true" body1="[1-3-1]" body2="[0-3-1]" anchor=" -0.402423 -0.135484 0.600501" />
<connect name="kinematic_link_2-1" active="true" body1="[1-3-1]" body2="[2-3-1]" anchor=" -0.402423 -0.135484 0.600501" />
<connect name="kinematic_link_3-0" active="true" body1="[1-4-1]" body2="[2-4-1]" anchor=" -0.359980 0.075144 0.636922" />
<connect name="kinematic_link_4-0" active="true" body1="[2-3-1]" body2="[0-3-1]" anchor=" 0.318545 -0.280767 0.600501" />
<connect name="kinematic_link_4-1" active="true" body1="[2-3-1]" body2="[1-3-1]" anchor=" 0.318545 -0.280767 0.600501" />
<connect name="kinematic_link_5-0" active="true" body1="[2-4-1]" body2="[1-4-1]" anchor=" 0.360988 -0.070139 0.636922" /></equality><actuator>

<intvelocity name="Member-0-1" joint="Linear-0-1" kp="18000"  kv="10000" inheritrange="1" />
<intvelocity name="Member-0-2" joint="Linear-0-2" kp="18000"  kv="10000" inheritrange="1" />
<intvelocity name="Member-0-3" joint="Linear-0-3" kp="18000"  kv="10000" inheritrange="1" />
<intvelocity name="Member-0-4" joint="Linear-0-1" kp="1"  kv="1" inheritrange="1" />
<intvelocity name="Member-0-5" joint="Linear-0-1" kp="1"  kv="1" inheritrange="1" />
<intvelocity name="Member-1-2" joint="Linear-1-2" kp="18000"  kv="10000" inheritrange="1" />
<intvelocity name="Member-1-3" joint="Linear-1-3" kp="18000"  kv="10000" inheritrange="1" />
<intvelocity name="Member-1-4" joint="Linear-1-4" kp="18000"  kv="10000" inheritrange="1" />
<intvelocity name="Member-1-5" joint="Linear-0-1" kp="1"  kv="1" inheritrange="1" />
<intvelocity name="Member-2-3" joint="Linear-2-3" kp="18000"  kv="10000" inheritrange="1" />
<intvelocity name="Member-2-4" joint="Linear-2-4" kp="18000"  kv="10000" inheritrange="1" />
<intvelocity name="Member-2-5" joint="Linear-0-1" kp="1"  kv="1" inheritrange="1" />
<intvelocity name="Member-3-4" joint="Linear-0-1" kp="1"  kv="1" inheritrange="1" />
<intvelocity name="Member-3-5" joint="Linear-0-1" kp="1"  kv="1" inheritrange="1" />
<intvelocity name="Member-4-5" joint="Linear-0-1" kp="1"  kv="1" inheritrange="1" />


</actuator>
</mujoco>
