<mujoco model="2-tet-1">
  <compiler angle="radian" meshdir="assets" autolimits="true"/>
  <option gravity="0 0 -9.81" timestep="0.002" integrator="implicit"/>

  <option cone="elliptic" impratio="10"/>

  <asset>
    <material name="metal" rgba="0.58 0.58 0.58 1"/>
    <material name="gray" rgba="0.4627 0.4627 0.4627 1"/>
    <material name="red" rgba="0.9 0.1 0.1 1"/>
    <texture name="grid" type="2d" builtin="checker" width="512" height="512" rgb1=".1 .2 .3" rgb2=".2 .3 .4"/>
    <material name="grid" texture="grid" texrepeat="1 1" texuniform="true" reflectance=".2"/>
  </asset>

  <worldbody>
  <body name="ground" pos="0 0 0">
  <freejoint/>

    <body name="[0-1-0]" pos="0.000000 0.000000 0.000000" >
    <geom type="sphere" name="(0)" pos="0.000000 0.000000 0.000000" size="0.05" material="red"contype="1" mass="10"/>

    <geom type="cylinder" pos="0.316694 0.386918 0.000000" axisangle="-0.773835 0.633387 0.000000 1.570796" size="0.025 0.45" material="metal" contype="1"/>
    <body name="[0-1-1]" pos="0.316694 0.386918 0.000000" >
        <geom type="cylinder" pos="0.153345 0.187348 0.000000" axisangle="-0.773835 0.633387 0.000000 1.570796" size="0.02 0.5" material="gray" contype="1"/>
        <joint name="Linear-0-1" type="slide" axis="0.633387 0.773835 0.000000" range="-0.242103 0.707897"/>


    <body name="[1-2-0]" pos="0.470039 0.574266 0.000000" >
    <geom type="sphere" name="(1)" pos="0.000000 0.000000 0.000000" size="0.05" material="red"contype="1" mass="10"/>
    <joint name="Passive1-2" type="ball" pos="0.000000 0.000000 0.000000" axis="0 1 0" damping=".9"/>
    <geom type="cylinder" pos="0.176734 -0.467723 -0.000000" axisangle="0.935447 0.353467 -0.000000 1.570796" size="0.025 0.45" material="metal" contype="1"/>
    <body name="[1-2-1]" pos="0.176734 -0.467723 -0.000000" >
        <geom type="cylinder" pos="0.085576 -0.226475 -0.000000" axisangle="0.935447 0.353467 -0.000000 1.570796" size="0.02 0.5" material="gray" contype="1"/>
        <joint name="Linear-1-2" type="slide" axis="0.353467 -0.935447 -0.000000" range="-0.242103 0.707897"/>


    <body name="[2-3-0]" pos="0.262309 -0.694198 -0.000000" >
    <geom type="sphere" name="(2)" pos="0.000000 0.000000 0.000000" size="0.05" material="red"contype="1" mass="10"/>
    <joint name="Passive2-3" type="ball" pos="0.000000 0.000000 0.000000" axis="0 1 0" damping=".9"/>
    <geom type="cylinder" pos="0.275698 0.169183 0.381271" axisangle="-0.338367 0.551396 0.000000 0.703563" size="0.025 0.45" material="metal" contype="1"/>
    <body name="[2-3-1]" pos="0.275698 0.169183 0.381271" >
        <geom type="cylinder" pos="0.133495 0.081920 0.184614" axisangle="-0.338367 0.551396 0.000000 0.703563" size="0.02 0.5" material="gray" contype="1"/>
        <joint name="Linear-2-3" type="slide" axis="0.551396 0.338367 0.762542" range="-0.242103 0.707897"/>


    <body name="[3-4-0]" pos="0.409193 0.251103 0.565885" >
    <geom type="sphere" name="(3)" pos="0.000000 0.000000 0.000000" size="0.05" material="red"contype="1" mass="10"/>
    <joint name="Passive3-4" type="ball" pos="0.000000 0.000000 0.000000" axis="0 1 0" damping=".9"/>
    <geom type="cylinder" pos="-0.259475 -0.424673 0.048219" axisangle="0.849347 -0.518950 0.000000 1.474209" size="0.025 0.45" material="metal" contype="1"/>
    <body name="[3-4-1]" pos="-0.259475 -0.424673 0.048219" >
        <geom type="cylinder" pos="-0.125640 -0.205630 0.023348" axisangle="0.849347 -0.518950 0.000000 1.474209" size="0.02 0.5" material="gray" contype="1"/>
        <joint name="Linear-3-4" type="slide" axis="-0.518950 -0.849347 0.096438" range="-0.242103 0.707897"/>


    <body name="[4-5-0]" pos="-0.385115 -0.630303 0.071567" >
    <geom type="sphere" name="(4)" pos="0.000000 0.000000 0.000000" size="0.05" material="red"contype="1" mass="10"/>
    <joint name="Passive4-5" type="ball" pos="0.000000 0.000000 0.000000" axis="0 1 0" damping=".9"/>
    <geom type="cylinder" pos="-0.239610 0.438333 -0.021242" axisangle="-0.876666 -0.479219 0.000000 1.613292" size="0.025 0.45" material="metal" contype="1"/>
    <body name="[4-5-1]" pos="-0.239610 0.438333 -0.021242" >
        <geom type="cylinder" pos="-0.116021 0.212244 -0.010285" axisangle="-0.876666 -0.479219 0.000000 1.613292" size="0.02 0.5" material="gray" contype="1"/>
        <joint name="Linear-4-5" type="slide" axis="-0.479219 0.876666 -0.042483" range="-0.242103 0.707897"/>
        <geom type="sphere" name="(5)" pos="-0.355630 0.650577 -0.031527" size="0.05" material="red"contype="1" mass="10"/>

    </body>
    </body>

    </body>
    </body>

    <body name="[3-5-0]" pos="0.409193 0.251103 0.565885" >

    <joint name="Passive3-5" type="ball" pos="0.000000 0.000000 0.000000" axis="0 1 0" damping=".9"/>
    <geom type="cylinder" pos="-0.499085 0.013660 0.026977" axisangle="-0.027320 -0.998170 0.000000 1.516816" size="0.025 0.45" material="metal" contype="1"/>
    <body name="[3-5-1]" pos="-0.499085 0.013660 0.026977" >
        <geom type="cylinder" pos="-0.241660 0.006614 0.013063" axisangle="-0.027320 -0.998170 0.000000 1.516816" size="0.02 0.5" material="gray" contype="1"/>
        <joint name="Linear-3-5" type="slide" axis="-0.998170 0.027320 0.053954" range="-0.242103 0.707897"/>


    </body>
    </body>

    </body>
    </body>

    <body name="[2-4-0]" pos="0.262309 -0.694198 -0.000000" >

    <joint name="Passive2-4" type="ball" pos="0.000000 0.000000 0.000000" axis="0 1 0" damping=".9"/>
    <geom type="cylinder" pos="0.016223 -0.255490 0.429490" axisangle="0.510980 0.032445 -0.000000 0.537522" size="0.025 0.45" material="metal" contype="1"/>
    <body name="[2-4-1]" pos="0.016223 -0.255490 0.429490" >
        <geom type="cylinder" pos="0.007855 -0.123710 0.207962" axisangle="0.510980 0.032445 -0.000000 0.537522" size="0.02 0.5" material="gray" contype="1"/>
        <joint name="Linear-2-4" type="slide" axis="0.032445 -0.510980 0.858980" range="-0.242103 0.707897"/>


    </body>
    </body>

    <body name="[2-5-0]" pos="0.262309 -0.694198 -0.000000" >

    <joint name="Passive2-5" type="ball" pos="0.000000 0.000000 0.000000" axis="0 1 0" damping=".9"/>
    <geom type="cylinder" pos="-0.223387 0.182843 0.408248" axisangle="-0.365686 -0.446774 0.000000 0.615480" size="0.025 0.45" material="metal" contype="1"/>
    <body name="[2-5-1]" pos="-0.223387 0.182843 0.408248" >
        <geom type="cylinder" pos="-0.108165 0.088534 0.197677" axisangle="-0.365686 -0.446774 0.000000 0.615480" size="0.02 0.5" material="gray" contype="1"/>
        <joint name="Linear-2-5" type="slide" axis="-0.446774 0.365686 0.816497" range="-0.242103 0.707897"/>


    </body>
    </body>

    </body>
    </body>

    <body name="[1-5-0]" pos="0.470039 0.574266 0.000000" >

    <joint name="Passive1-5" type="ball" pos="0.000000 0.000000 0.000000" axis="0 1 0" damping=".9"/>
    <geom type="cylinder" pos="-0.046653 -0.284880 0.408248" axisangle="0.569761 -0.093307 0.000000 0.615480" size="0.025 0.45" material="metal" contype="1"/>
    <body name="[1-5-1]" pos="-0.046653 -0.284880 0.408248" >
        <geom type="cylinder" pos="-0.022590 -0.137941 0.197677" axisangle="0.569761 -0.093307 0.000000 0.615480" size="0.02 0.5" material="gray" contype="1"/>
        <joint name="Linear-1-5" type="slide" axis="-0.093307 -0.569761 0.816497" range="-0.242103 0.707897"/>


    </body>
    </body>

    </body>
    </body>

    <body name="[0-2-0]" pos="0.000000 0.000000 0.000000" >

    <joint name="Passive0-2" type="ball" pos="0.000000 0.000000 0.000000" axis="0 1 0" damping=".9"/>
    <geom type="cylinder" pos="0.493427 -0.080806 -0.000000" axisangle="0.161612 0.986854 -0.000000 1.570796" size="0.025 0.45" material="metal" contype="1"/>
    <body name="[0-2-1]" pos="0.493427 -0.080806 -0.000000" >
        <geom type="cylinder" pos="0.238921 -0.039127 -0.000000" axisangle="0.161612 0.986854 -0.000000 1.570796" size="0.02 0.5" material="gray" contype="1"/>
        <joint name="Linear-0-2" type="slide" axis="0.986854 -0.161612 -0.000000" range="-0.242103 0.707897"/>


    </body>
    </body>

    <body name="[0-5-0]" pos="0.000000 0.000000 0.000000" >

    <joint name="Passive0-5" type="ball" pos="0.000000 0.000000 0.000000" axis="0 1 0" damping=".9"/>
    <geom type="cylinder" pos="0.270040 0.102037 0.408248" axisangle="-0.204074 0.540081 0.000000 0.615480" size="0.025 0.45" material="metal" contype="1"/>
    <body name="[0-5-1]" pos="0.270040 0.102037 0.408248" >
        <geom type="cylinder" pos="0.130755 0.049407 0.197677" axisangle="-0.204074 0.540081 0.000000 0.615480" size="0.02 0.5" material="gray" contype="1"/>
        <joint name="Linear-0-5" type="slide" axis="0.540081 0.204074 0.816497" range="-0.242103 0.707897"/>


    </body>
    </body>
    </body> </worldbody> <equality>
<connect name="kinematic_link_0-0" active="true" body1="[0-2-1]" body2="[1-2-1]" anchor=" 0.732348 -0.119933 -0.000000" />
<connect name="kinematic_link_1-0" active="true" body1="[0-5-1]" body2="[1-5-1]" anchor=" 0.400796 0.151444 0.605925" />
<connect name="kinematic_link_1-1" active="true" body1="[0-5-1]" body2="[2-5-1]" anchor=" 0.400796 0.151444 0.605925" />
<connect name="kinematic_link_1-2" active="true" body1="[0-5-1]" body2="[3-5-1]" anchor=" 0.400796 0.151444 0.605925" />
<connect name="kinematic_link_1-3" active="true" body1="[0-5-1]" body2="[4-5-1]" anchor=" 0.400796 0.151444 0.605925" />
<connect name="kinematic_link_2-0" active="true" body1="[1-5-1]" body2="[0-5-1]" anchor=" -0.069243 -0.422821 0.605925" />
<connect name="kinematic_link_2-1" active="true" body1="[1-5-1]" body2="[2-5-1]" anchor=" -0.069243 -0.422821 0.605925" />
<connect name="kinematic_link_2-2" active="true" body1="[1-5-1]" body2="[3-5-1]" anchor=" -0.069243 -0.422821 0.605925" />
<connect name="kinematic_link_2-3" active="true" body1="[1-5-1]" body2="[4-5-1]" anchor=" -0.069243 -0.422821 0.605925" />
<connect name="kinematic_link_3-0" active="true" body1="[2-4-1]" body2="[3-4-1]" anchor=" 0.024078 -0.379200 0.637452" />
<connect name="kinematic_link_4-0" active="true" body1="[2-5-1]" body2="[0-5-1]" anchor=" -0.331552 0.271377 0.605925" />
<connect name="kinematic_link_4-1" active="true" body1="[2-5-1]" body2="[1-5-1]" anchor=" -0.331552 0.271377 0.605925" />
<connect name="kinematic_link_4-2" active="true" body1="[2-5-1]" body2="[3-5-1]" anchor=" -0.331552 0.271377 0.605925" />
<connect name="kinematic_link_4-3" active="true" body1="[2-5-1]" body2="[4-5-1]" anchor=" -0.331552 0.271377 0.605925" />
<connect name="kinematic_link_5-0" active="true" body1="[3-5-1]" body2="[0-5-1]" anchor=" -0.740745 0.020274 0.040040" />
<connect name="kinematic_link_5-1" active="true" body1="[3-5-1]" body2="[1-5-1]" anchor=" -0.740745 0.020274 0.040040" />
<connect name="kinematic_link_5-2" active="true" body1="[3-5-1]" body2="[2-5-1]" anchor=" -0.740745 0.020274 0.040040" />
<connect name="kinematic_link_5-3" active="true" body1="[3-5-1]" body2="[4-5-1]" anchor=" -0.740745 0.020274 0.040040" />
<connect name="kinematic_link_6-0" active="true" body1="[4-5-1]" body2="[0-5-1]" anchor=" -0.355630 0.650577 -0.031527" />
<connect name="kinematic_link_6-1" active="true" body1="[4-5-1]" body2="[1-5-1]" anchor=" -0.355630 0.650577 -0.031527" />
<connect name="kinematic_link_6-2" active="true" body1="[4-5-1]" body2="[2-5-1]" anchor=" -0.355630 0.650577 -0.031527" />
<connect name="kinematic_link_6-3" active="true" body1="[4-5-1]" body2="[3-5-1]" anchor=" -0.355630 0.650577 -0.031527" /></equality><actuator>



<intvelocity name="Member-0-1" joint="Linear-0-1" kp="18000"  kv="10000" inheritrange="1" />
<intvelocity name="Member-0-2" joint="Linear-0-2" kp="18000"  kv="10000" inheritrange="1" />
<intvelocity name="Member-0-3" joint="Linear-0-1" kp="1"  kv="1" inheritrange="1" />
<intvelocity name="Member-0-4" joint="Linear-0-1" kp="1"  kv="1" inheritrange="1" />
<intvelocity name="Member-0-5" joint="Linear-0-5" kp="18000"  kv="10000" inheritrange="1" />
<intvelocity name="Member-1-2" joint="Linear-1-2" kp="18000"  kv="10000" inheritrange="1" />
<intvelocity name="Member-1-3" joint="Linear-0-1" kp="1"  kv="1" inheritrange="1" />
<intvelocity name="Member-1-4" joint="Linear-0-1" kp="1"  kv="1" inheritrange="1" />
<intvelocity name="Member-1-5" joint="Linear-1-5" kp="18000"  kv="10000" inheritrange="1" />
<intvelocity name="Member-2-3" joint="Linear-2-3" kp="18000"  kv="10000" inheritrange="1" />
<intvelocity name="Member-2-4" joint="Linear-2-4" kp="18000"  kv="10000" inheritrange="1" />
<intvelocity name="Member-2-5" joint="Linear-2-5" kp="18000"  kv="10000" inheritrange="1" />
<intvelocity name="Member-3-4" joint="Linear-3-4" kp="18000"  kv="10000" inheritrange="1" />
<intvelocity name="Member-3-5" joint="Linear-3-5" kp="18000"  kv="10000" inheritrange="1" />
<intvelocity name="Member-4-5" joint="Linear-4-5" kp="18000"  kv="10000" inheritrange="1" />



</actuator>
</mujoco>
