<mujoco model="3-tet">
  <compiler angle="radian" meshdir="assets" autolimits="true"/>
  <option gravity="0 0 -9.81" timestep="0.002" integrator="implicit"/>

  <option cone="elliptic" impratio="10"/>

  <asset>
    <material name="metal" rgba="0.58 0.58 0.58 1"/>
    <material name="gray" rgba="0.4627 0.4627 0.4627 1"/>
    <material name="red" rgba="0.9 0.1 0.1 1"/>
    <texture name="grid" type="2d" builtin="checker" width="512" height="512" rgb1=".1 .2 .3" rgb2=".2 .3 .4"/>
    <material name="grid" texture="grid" texrepeat="1 1" texuniform="true" reflectance=".2"/>
  </asset>

  <worldbody>
  <body name="ground" pos="0 0 0">
  <freejoint/>

    <body name="[0-1-0]" pos="0.000000 0.000000 0.000000" >
    <geom type="sphere" name="(0)" pos="0.000000 0.000000 0.000000" size="0.05" material="red"contype="1" mass="10"/>

    <geom type="cylinder" pos="0.443695 0.230509 0.000000" axisangle="-0.461018 0.887391 0.000000 1.570796" size="0.025 0.45" material="metal" contype="1"/>
    <body name="[0-1-1]" pos="0.443695 0.230509 0.000000" >
        <geom type="cylinder" pos="0.235861 0.122535 0.000000" axisangle="-0.461018 0.887391 0.000000 1.570796" size="0.02 0.5" material="gray" contype="1"/>
        <joint name="Linear-0-1" type="slide" axis="0.887391 0.461018 0.000000" range="-0.265791 0.684209"/>


    <body name="[1-2-0]" pos="0.679556 0.353044 0.000000" >
    <geom type="sphere" name="(1)" pos="0.000000 0.000000 0.000000" size="0.05" material="red"contype="1" mass="10"/>
    <joint name="Passive1-2" type="ball" pos="0.000000 0.000000 0.000000" axis="0 1 0" damping=".9"/>
    <geom type="cylinder" pos="0.000002 -0.500000 -0.000000" axisangle="1.000000 0.000004 -0.000000 1.570796" size="0.025 0.45" material="metal" contype="1"/>
    <body name="[1-2-1]" pos="0.000002 -0.500000 -0.000000" >
        <geom type="cylinder" pos="0.000001 -0.167106 -0.000000" axisangle="1.000000 0.000004 -0.000000 1.570796" size="0.02 0.5" material="gray" contype="1"/>
        <joint name="Linear-1-2" type="slide" axis="0.000004 -1.000000 -0.000000" range="-0.167106 0.782894"/>


    <body name="[2-3-0]" pos="0.000002 -0.667106 -0.000000" >
    <geom type="sphere" name="(2)" pos="0.000000 0.000000 0.000000" size="0.05" material="red"contype="1" mass="10"/>
    <joint name="Passive2-3" type="ball" pos="0.000000 0.000000 0.000000" axis="0 1 0" damping=".9"/>
    <geom type="cylinder" pos="-0.221369 0.225463 0.387508" axisangle="-0.450926 -0.442738 0.000000 0.684057" size="0.025 0.45" material="metal" contype="1"/>
    <body name="[2-3-1]" pos="-0.221369 0.225463 0.387508" >
        <geom type="cylinder" pos="-0.130222 0.132630 0.227954" axisangle="-0.450926 -0.442738 0.000000 0.684057" size="0.02 0.5" material="gray" contype="1"/>
        <joint name="Linear-2-3" type="slide" axis="-0.442738 0.450926 0.775015" range="-0.294129 0.655871"/>


    <body name="[3-4-0]" pos="-0.351591 0.358093 0.615462" >
    <geom type="sphere" name="(3)" pos="0.000000 0.000000 0.000000" size="0.05" material="red"contype="1" mass="10"/>
    <joint name="Passive3-4" type="ball" pos="0.000000 0.000000 0.000000" axis="0 1 0" damping=".9"/>
    <geom type="cylinder" pos="0.500000 0.000000 -0.000004" axisangle="-0.000001 1.000000 0.000000 1.570805" size="0.025 0.45" material="metal" contype="1"/>
    <body name="[3-4-1]" pos="0.500000 0.000000 -0.000004" >
        <geom type="cylinder" pos="0.145817 0.000000 -0.000001" axisangle="-0.000001 1.000000 0.000000 1.570805" size="0.02 0.5" material="gray" contype="1"/>
        <joint name="Linear-3-4" type="slide" axis="1.000000 0.000001 -0.000008" range="-0.145817 0.804183"/>


    <body name="[4-5-0]" pos="0.645817 0.000000 -0.000005" >
    <geom type="sphere" name="(4)" pos="0.000000 0.000000 0.000000" size="0.05" material="red"contype="1" mass="10"/>
    <joint name="Passive4-5" type="ball" pos="0.000000 0.000000 0.000000" axis="0 1 0" damping=".9"/>
    <geom type="cylinder" pos="0.240573 -0.000002 -0.438320" axisangle="0.000005 0.481146 -0.000000 2.639632" size="0.025 0.45" material="metal" contype="1"/>
    <body name="[4-5-1]" pos="0.240573 -0.000002 -0.438320" >
        <geom type="cylinder" pos="0.069331 -0.000001 -0.126319" axisangle="0.000005 0.481146 -0.000000 2.639632" size="0.02 0.5" material="gray" contype="1"/>
        <joint name="Linear-4-5" type="slide" axis="0.481146 -0.000005 -0.876641" range="-0.144095 0.805905"/>
        <geom type="sphere" name="(5)" pos="0.309903 -0.000003 -0.564640" size="0.05" material="red"contype="1" mass="10"/>

    </body>
    </body>

    </body>
    </body>

    </body>
    </body>

    <body name="[2-4-0]" pos="0.000002 -0.667106 -0.000000" >

    <joint name="Passive2-4" type="ball" pos="0.000000 0.000000 0.000000" axis="0 1 0" damping=".9"/>
    <geom type="cylinder" pos="0.221338 0.225472 0.387520" axisangle="-0.450945 0.442676 0.000000 0.684018" size="0.025 0.45" material="metal" contype="1"/>
    <body name="[2-4-1]" pos="0.221338 0.225472 0.387520" >
        <geom type="cylinder" pos="0.130180 0.132612 0.227920" axisangle="-0.450945 0.442676 0.000000 0.684018" size="0.02 0.5" material="gray" contype="1"/>
        <joint name="Linear-2-4" type="slide" axis="0.442676 0.450945 0.775040" range="-0.294076 0.655924"/>


    </body>
    </body>

    <body name="[2-5-0]" pos="0.000002 -0.667106 -0.000000" >

    <joint name="Passive2-5" type="ball" pos="0.000000 0.000000 0.000000" axis="0 1 0" damping=".9"/>
    <geom type="cylinder" pos="0.443702 0.230495 -0.000000" axisangle="-0.460991 0.887405 0.000000 1.570796" size="0.025 0.45" material="metal" contype="1"/>
    <body name="[2-5-1]" pos="0.443702 0.230495 -0.000000" >
        <geom type="cylinder" pos="0.235928 0.122560 -0.000000" axisangle="-0.460991 0.887405 0.000000 1.570796" size="0.02 0.5" material="gray" contype="1"/>
        <joint name="Linear-2-5" type="slide" axis="0.887405 0.460991 -0.000000" range="-0.265863 0.684137"/>


    </body>
    </body>

    </body>
    </body>

    <body name="[1-3-0]" pos="0.679556 0.353044 0.000000" >

    <joint name="Passive1-3" type="ball" pos="0.000000 0.000000 0.000000" axis="0 1 0" damping=".9"/>
    <geom type="cylinder" pos="-0.221368 -0.225461 0.387509" axisangle="0.450922 -0.442737 0.000000 0.684052" size="0.025 0.45" material="metal" contype="1"/>
    <body name="[1-3-1]" pos="-0.221368 -0.225461 0.387509" >
        <geom type="cylinder" pos="-0.130219 -0.132627 0.227951" axisangle="0.450922 -0.442737 0.000000 0.684052" size="0.02 0.5" material="gray" contype="1"/>
        <joint name="Linear-1-3" type="slide" axis="-0.442737 -0.450922 0.775018" range="-0.294124 0.655876"/>


    </body>
    </body>

    <body name="[1-4-0]" pos="0.679556 0.353044 0.000000" >

    <joint name="Passive1-4" type="ball" pos="0.000000 0.000000 0.000000" axis="0 1 0" damping=".9"/>
    <geom type="cylinder" pos="0.221340 -0.225470 0.387520" axisangle="0.450939 0.442680 -0.000000 0.684017" size="0.025 0.45" material="metal" contype="1"/>
    <body name="[1-4-1]" pos="0.221340 -0.225470 0.387520" >
        <geom type="cylinder" pos="0.130181 -0.132610 0.227919" axisangle="0.450939 0.442680 -0.000000 0.684017" size="0.02 0.5" material="gray" contype="1"/>
        <joint name="Linear-1-4" type="slide" axis="0.442680 -0.450939 0.775041" range="-0.294074 0.655926"/>


    </body>
    </body>

    <body name="[1-5-0]" pos="0.679556 0.353044 0.000000" >

    <joint name="Passive1-5" type="ball" pos="0.000000 0.000000 0.000000" axis="0 1 0" damping=".9"/>
    <geom type="cylinder" pos="0.443702 -0.230496 -0.000000" axisangle="0.460992 0.887405 -0.000000 1.570796" size="0.025 0.45" material="metal" contype="1"/>
    <body name="[1-5-1]" pos="0.443702 -0.230496 -0.000000" >
        <geom type="cylinder" pos="0.235933 -0.122563 -0.000000" axisangle="0.460992 0.887405 -0.000000 1.570796" size="0.02 0.5" material="gray" contype="1"/>
        <joint name="Linear-1-5" type="slide" axis="0.887405 -0.460992 -0.000000" range="-0.265868 0.684132"/>


    </body>
    </body>

    </body>
    </body>

    <body name="[0-2-0]" pos="0.000000 0.000000 0.000000" >

    <joint name="Passive0-2" type="ball" pos="0.000000 0.000000 0.000000" axis="0 1 0" damping=".9"/>
    <geom type="cylinder" pos="0.443696 -0.230508 0.000000" axisangle="0.461017 0.887392 -0.000000 1.570796" size="0.025 0.45" material="metal" contype="1"/>
    <body name="[0-2-1]" pos="0.443696 -0.230508 0.000000" >
        <geom type="cylinder" pos="0.235864 -0.122536 0.000000" axisangle="0.461017 0.887392 -0.000000 1.570796" size="0.02 0.5" material="gray" contype="1"/>
        <joint name="Linear-0-2" type="slide" axis="0.887392 -0.461017 0.000000" range="-0.265795 0.684205"/>


    </body>
    </body>

    <body name="[0-3-0]" pos="0.000000 0.000000 0.000000" >

    <joint name="Passive0-3" type="ball" pos="0.000000 0.000000 0.000000" axis="0 1 0" damping=".9"/>
    <geom type="cylinder" pos="0.240510 0.000002 0.438355" axisangle="-0.000003 0.481020 0.000000 0.501818" size="0.025 0.45" material="metal" contype="1"/>
    <body name="[0-3-1]" pos="0.240510 0.000002 0.438355" >
        <geom type="cylinder" pos="0.069275 0.000000 0.126260" axisangle="-0.000003 0.481020 0.000000 0.501818" size="0.02 0.5" material="gray" contype="1"/>
        <joint name="Linear-0-3" type="slide" axis="0.481020 0.000003 0.876709" range="-0.144016 0.805984"/>


    </body>
    </body>
    </body> </worldbody> <equality>
<connect name="kinematic_link_0-0" active="true" body1="[0-2-1]" body2="[1-2-1]" anchor=" 0.679560 -0.353044 0.000000" />
<connect name="kinematic_link_1-0" active="true" body1="[0-3-1]" body2="[1-3-1]" anchor=" 0.309785 0.000002 0.564615" />
<connect name="kinematic_link_1-1" active="true" body1="[0-3-1]" body2="[2-3-1]" anchor=" 0.309785 0.000002 0.564615" />
<connect name="kinematic_link_2-0" active="true" body1="[1-3-1]" body2="[0-3-1]" anchor=" -0.351588 -0.358088 0.615461" />
<connect name="kinematic_link_2-1" active="true" body1="[1-3-1]" body2="[2-3-1]" anchor=" -0.351588 -0.358088 0.615461" />
<connect name="kinematic_link_3-0" active="true" body1="[1-4-1]" body2="[2-4-1]" anchor=" 0.351521 -0.358079 0.615440" />
<connect name="kinematic_link_3-1" active="true" body1="[1-4-1]" body2="[3-4-1]" anchor=" 0.351521 -0.358079 0.615440" />
<connect name="kinematic_link_4-0" active="true" body1="[1-5-1]" body2="[2-5-1]" anchor=" 0.679635 -0.353059 -0.000000" />
<connect name="kinematic_link_4-1" active="true" body1="[1-5-1]" body2="[4-5-1]" anchor=" 0.679635 -0.353059 -0.000000" />
<connect name="kinematic_link_5-0" active="true" body1="[2-4-1]" body2="[1-4-1]" anchor=" 0.351519 0.358084 0.615440" />
<connect name="kinematic_link_5-1" active="true" body1="[2-4-1]" body2="[3-4-1]" anchor=" 0.351519 0.358084 0.615440" />
<connect name="kinematic_link_6-0" active="true" body1="[2-5-1]" body2="[1-5-1]" anchor=" 0.679631 0.353056 -0.000000" />
<connect name="kinematic_link_6-1" active="true" body1="[2-5-1]" body2="[4-5-1]" anchor=" 0.679631 0.353056 -0.000000" />
<connect name="kinematic_link_7-0" active="true" body1="[4-5-1]" body2="[1-5-1]" anchor=" 0.309903 -0.000003 -0.564640" />
<connect name="kinematic_link_7-1" active="true" body1="[4-5-1]" body2="[2-5-1]" anchor=" 0.309903 -0.000003 -0.564640" /></equality><actuator>

<intvelocity name="Member-0-1" joint="Linear-0-1" kp="18000"  kv="10000" inheritrange="1" />
<intvelocity name="Member-0-2" joint="Linear-0-2" kp="18000"  kv="10000" inheritrange="1" />
<intvelocity name="Member-0-3" joint="Linear-0-3" kp="18000"  kv="10000" inheritrange="1" />
<intvelocity name="Member-0-4" joint="Linear-0-1" kp="1"  kv="1" inheritrange="1" />
<intvelocity name="Member-0-5" joint="Linear-0-1" kp="1"  kv="1" inheritrange="1" />
<intvelocity name="Member-1-2" joint="Linear-1-2" kp="18000"  kv="10000" inheritrange="1" />
<intvelocity name="Member-1-3" joint="Linear-1-3" kp="18000"  kv="10000" inheritrange="1" />
<intvelocity name="Member-1-4" joint="Linear-1-4" kp="18000"  kv="10000" inheritrange="1" />
<intvelocity name="Member-1-5" joint="Linear-1-5" kp="18000"  kv="10000" inheritrange="1" />
<intvelocity name="Member-2-3" joint="Linear-2-3" kp="18000"  kv="10000" inheritrange="1" />
<intvelocity name="Member-2-4" joint="Linear-2-4" kp="18000"  kv="10000" inheritrange="1" />
<intvelocity name="Member-2-5" joint="Linear-2-5" kp="18000"  kv="10000" inheritrange="1" />
<intvelocity name="Member-3-4" joint="Linear-3-4" kp="18000"  kv="10000" inheritrange="1" />
<intvelocity name="Member-3-5" joint="Linear-0-1" kp="1"  kv="1" inheritrange="1" />
<intvelocity name="Member-4-5" joint="Linear-4-5" kp="18000"  kv="10000" inheritrange="1" />

</actuator>
</mujoco>